<?xml version="1.0" ?>
<!-- =================================================================================== -->
<!-- |    This document was autogenerated by xacro from robot_description.urdf.xacro   | -->
<!-- |    EDITING THIS FILE BY HAND IS NOT RECOMMENDED                                 | -->
<!-- =================================================================================== -->
<robot name="robot">
  <!-- World 프레임 추가 -->
  <link name="world"/>
  <joint name="base_link_joint" type="fixed">
    <origin rpy="0 0 0" xyz="0 0 0"/>
    <parent link="world"/>
    <child link="base_link"/>
  </joint>
  <link name="base_link">
    <visual>
      <geometry>
        <mesh filename="package://robomaster_om_description/meshes/DAE/base/base_link_robomaster.dae"/>
      </geometry>
    </visual>
    <collision>
      <geometry>
        <mesh filename="package://robomaster_om_description/meshes/STL/base/base_link.stl"/>
      </geometry>
    </collision>
    <inertial>
      <origin xyz="-0.178 0 0"/>
      <mass value="6.44"/>
      <inertia ixx="0.055" ixy="0" ixz="0.005" iyy="0.143" iyz="0" izz="0.1637"/>
    </inertial>
    <surface>
      <friction>
        <ode>
          <mu>0.8</mu>
          <mu2>0.8</mu2>
          <kp>1e15</kp>
          <kd>1e13</kd>
        </ode>
      </friction>
      <bounce>
        <restitution_coefficient>0.01</restitution_coefficient>
        <threshold>10</threshold>
      </bounce>
      <contact>
        <ode>
          <max_vel>0.01</max_vel>
          <minDepth>0</minDepth>
          <contact_surface_layer>0</contact_surface_layer>
        </ode>
      </contact>
    </surface>
  </link>
  <!-- World -->
  <gazebo reference="world">
  </gazebo>
  <!-- Link1 -->
  <RefLink ref="link1"/>
  <!-- Link2 -->
  <RefLink ref="link2"/>
  <!-- Link3 -->
  <RefLink ref="link3"/>
  <!-- Link4 -->
  <RefLink ref="link4"/>
  <!-- Link5 -->
  <RefLink ref="link5"/>
  <!-- Link6 -->
  <RefLink ref="link6"/>
  <!-- Link7 -->
  <RefLink ref="link7"/>
  <!-- gripper_link -->
  <RefLink ref="gripper_link"/>
  <!-- gripper_link_sub -->
  <RefLink ref="gripper_link_sub"/>
  <!-- end effector link -->
  <gazebo reference="end_effector_link">
    <material>Gazebo/Red</material>
  </gazebo>
  <!-- ros_control plugin -->
  <gazebo>
    <plugin filename="libgazebo_ros_control.so" name="gazebo_ros_control">
      <!-- <robotNamespace>open_manipulator_6dof</robotNamespace> -->
      <controlPeriod>0.001</controlPeriod>
      <robotSimType>gazebo_ros_control/DefaultRobotHWSim</robotSimType>
    </plugin>
  </gazebo>
  <material name="black">
    <color rgba="0.0 0.0 0.0 1.0"/>
  </material>
  <material name="white">
    <color rgba="1.0 1.0 1.0 1.0"/>
  </material>
  <material name="red">
    <color rgba="0.8 0.0 0.0 1.0"/>
  </material>
  <material name="blue">
    <color rgba="0.0 0.0 0.8 1.0"/>
  </material>
  <material name="green">
    <color rgba="0.0 0.8 0.0 1.0"/>
  </material>
  <material name="grey">
    <color rgba="0.5 0.5 0.5 1.0"/>
  </material>
  <material name="orange">
    <color rgba="1.0 0.4235294117647059 0.0392156862745098 1.0"/>
  </material>
  <material name="brown">
    <color rgba="0.8705882352941177 0.8117647058823529 0.7647058823529411 1.0"/>
  </material>
  <!-- World -->
  <!-- <link name="world">
  </link> -->
  <!-- World fixed joint-->
  <!-- <joint name="world_fixed" type="fixed">
    <origin xyz="0 0 0" rpy="0 0 0"/>
    <parent link="world"/>
    <child link="link1"/>
  </joint> -->
  <!-- Link 1 -->
  <link name="link1">
    <visual>
      <origin rpy="0 0 0" xyz="0 0 0"/>
      <geometry>
        <mesh filename="package://robomaster_om_description/meshes/STL/chain_link1.stl" scale="0.001 0.001 0.001"/>
      </geometry>
      <material name="grey"/>
    </visual>
    <collision>
      <origin rpy="0 0 0" xyz="0 0 0"/>
      <geometry>
        <mesh filename="package://robomaster_om_description/meshes/STL/chain_link1.stl" scale="0.001 0.001 0.001"/>
      </geometry>
    </collision>
    <!--    <inertial>
      <origin xyz="0 0 0" />
      <mass value="0.082" />
      <inertia ixx="0.1" ixy="0.0" ixz="0.0"
               iyy="0.1" iyz="0.0"
               izz="0.1" />
    </inertial>-->
    <inertial>
      <origin xyz="3.0876154e-04 0.0000000e+00 -1.2176461e-04"/>
      <mass value="7.9119962e-02"/>
      <inertia ixx="1.2505234e-05" ixy="0.0" ixz="-1.7855208e-07" iyy="2.1898364e-05" iyz="0.0" izz="1.9267361e-05"/>
    </inertial>
  </link>
  <!-- Joint 1 -->
  <joint name="joint1" type="revolute">
    <parent link="link1"/>
    <child link="link2"/>
    <origin rpy="0 0 0" xyz="0.012 0.0 0.017"/>
    <axis xyz="0 0 1"/>
    <limit effort="1" lower="-2.827433388230814" upper="2.827433388230814" velocity="4.8"/>
  </joint>
  <transmission name="tran1">
    <type>transmission_interface/SimpleTransmission</type>
    <joint name="joint1">
      <hardwareInterface>hardware_interface/PositionJointInterface</hardwareInterface>
    </joint>
    <actuator name="motor1">
      <hardwareInterface>hardware_interface/PositionJointInterface</hardwareInterface>
      <mechanicalReduction>1</mechanicalReduction>
    </actuator>
  </transmission>
  <!--  Link 2 -->
  <link name="link2">
    <visual>
      <origin rpy="0 0 0" xyz="0 0 0.019"/>
      <geometry>
        <mesh filename="package://robomaster_om_description/meshes/STL/chain_link2.stl" scale="0.001 0.001 0.001"/>
      </geometry>
      <material name="grey"/>
    </visual>
    <collision>
      <origin rpy="0 0 0" xyz="0 0 0.019"/>
      <geometry>
        <mesh filename="package://robomaster_om_description/meshes/STL/chain_link2.stl" scale="0.001 0.001 0.001"/>
      </geometry>
    </collision>
    <!--    <inertial>
      <origin xyz="0 0 0" />
      <mass value="0.098" />
      <inertia ixx="0.1" ixy="0.0" ixz="0.0"
               iyy="0.1" iyz="0.0"
               izz="0.1" />
    </inertial>-->
    <inertial>
      <origin xyz="-3.0184870e-04 5.4043684e-04 0.047433463999999995"/>
      <mass value="9.8406837e-02"/>
      <inertia ixx="3.4543422e-05" ixy="-1.6031095e-08" ixz="-3.8375155e-07" iyy="3.2689329e-05" iyz="2.8511935e-08" izz="1.8850320e-05"/>
    </inertial>
  </link>
  <!--  Joint 2 -->
  <joint name="joint2" type="revolute">
    <parent link="link2"/>
    <child link="link3"/>
    <origin rpy="0 0 0" xyz="0.0 0.0 0.0595"/>
    <axis xyz="0 1 0"/>
    <limit effort="1" lower="-2.0420352248333655" upper="2.1048670779051615" velocity="4.8"/>
  </joint>
  <transmission name="tran2">
    <type>transmission_interface/SimpleTransmission</type>
    <joint name="joint2">
      <hardwareInterface>hardware_interface/PositionJointInterface</hardwareInterface>
    </joint>
    <actuator name="motor2">
      <hardwareInterface>hardware_interface/PositionJointInterface</hardwareInterface>
      <mechanicalReduction>1</mechanicalReduction>
    </actuator>
  </transmission>
  <!--  Link 3 -->
  <link name="link3">
    <visual>
      <origin rpy="0 0 0" xyz="0 0 0"/>
      <geometry>
        <mesh filename="package://robomaster_om_description/meshes/STL/chain_link3.stl" scale="0.001 0.001 0.001"/>
      </geometry>
      <material name="grey"/>
    </visual>
    <collision>
      <origin rpy="0 0 0" xyz="0 0 0"/>
      <geometry>
        <mesh filename="package://robomaster_om_description/meshes/STL/chain_link3.stl" scale="0.001 0.001 0.001"/>
      </geometry>
    </collision>
    <!-- <inertial>
      <origin xyz="0 0 0" />
      <mass value="0.131" />
      <inertia ixx="0.1" ixy="0.0" ixz="0.0"
               iyy="0.1" iyz="0.0"
               izz="0.1" />
    </inertial> -->
    <inertial>
      <origin xyz="1.0308393e-02 3.7743363e-04 1.0170197e-01"/>
      <mass value="1.3850917e-01"/>
      <inertia ixx="3.3055381e-04" ixy="-9.7940978e-08" ixz="-3.8505711e-05" iyy="3.4290447e-04" iyz="-1.5717516e-06" izz="6.0346498e-05"/>
    </inertial>
  </link>
  <!--  Joint 3 -->
  <joint name="joint3" type="revolute">
    <parent link="link3"/>
    <child link="link4"/>
    <origin rpy="0 0 0" xyz="0.0 0 0.124"/>
    <axis xyz="0 1 0"/>
    <limit effort="1" lower="-1.8849555921538759" upper="2.1362830044410597" velocity="4.8"/>
  </joint>
  <transmission name="tran3">
    <type>transmission_interface/SimpleTransmission</type>
    <joint name="joint3">
      <hardwareInterface>hardware_interface/PositionJointInterface</hardwareInterface>
    </joint>
    <actuator name="motor3">
      <hardwareInterface>hardware_interface/PositionJointInterface</hardwareInterface>
      <mechanicalReduction>1</mechanicalReduction>
    </actuator>
  </transmission>
  <!--  Link 4 -->
  <link name="link4">
    <visual>
      <origin rpy="0 0 0" xyz="0 0 0"/>
      <geometry>
        <mesh filename="package://robomaster_om_description/meshes/STL/chain_link4.stl" scale="0.001 0.001 0.001"/>
      </geometry>
      <material name="grey"/>
    </visual>
    <collision>
      <origin rpy="0 0 0" xyz="0 0 0"/>
      <geometry>
        <mesh filename="package://robomaster_om_description/meshes/STL/chain_link4.stl" scale="0.001 0.001 0.001"/>
      </geometry>
    </collision>
    <!-- <inertial>
      <origin xyz="0 0 0" />
      <mass value="0.098" />
      <inertia ixx="0.1" ixy="0.0" ixz="0.0"
               iyy="0.1" iyz="0.0"
               izz="0.1" />
    </inertial> -->
    <inertial>
      <origin xyz="9.0909590e-02 3.8929816e-04 2.2413279e-04"/>
      <mass value="1.3274562e-01"/>
      <inertia ixx="3.0654178e-05" ixy="-1.2764155e-06" ixz="-2.6874417e-07" iyy="2.4230292e-04" iyz="1.1559550e-08" izz="2.5155057e-04"/>
    </inertial>
  </link>
  <!--  Joint 4 -->
  <joint name="joint4" type="revolute">
    <parent link="link4"/>
    <child link="link5"/>
    <origin rpy="0 0 0" xyz="0.0 0.0 0.045"/>
    <axis xyz="0 0 1"/>
    <limit effort="1" lower="-2.827433388230814" upper="2.827433388230814" velocity="4.8"/>
  </joint>
  <transmission name="tran4">
    <type>transmission_interface/SimpleTransmission</type>
    <joint name="joint4">
      <hardwareInterface>hardware_interface/PositionJointInterface</hardwareInterface>
    </joint>
    <actuator name="motor4">
      <hardwareInterface>hardware_interface/PositionJointInterface</hardwareInterface>
      <mechanicalReduction>1</mechanicalReduction>
    </actuator>
  </transmission>
  <!--  Link 5 -->
  <link name="link5">
    <visual>
      <origin rpy="0 0 0" xyz="0 0 0.019"/>
      <geometry>
        <mesh filename="package://robomaster_om_description/meshes/STL/chain_link5.stl" scale="0.001 0.001 0.001"/>
      </geometry>
      <material name="grey"/>
    </visual>
    <collision>
      <origin rpy="0 0 0" xyz="0 0 0.019"/>
      <geometry>
        <mesh filename="package://robomaster_om_description/meshes/STL/chain_link5.stl" scale="0.001 0.001 0.001"/>
      </geometry>
    </collision>
    <!-- <inertial>
      <origin xyz="0 0 0" />
      <mass value="0.098" />
      <inertia ixx="0.1" ixy="0.0" ixz="0.0"
               iyy="0.1" iyz="0.0"
               izz="0.1" />
    </inertial> -->
    <inertial>
      <origin xyz="4.4206755e-02 3.6839985e-07 8.9142216e-03"/>
      <mass value="1.4327573e-01"/>
      <inertia ixx="8.0870749e-05" ixy="0.0" ixz="-1.0157896e-06" iyy="7.5980465e-05" iyz="0.0" izz="9.3127351e-05"/>
    </inertial>
  </link>
  <!--  Joint 5 -->
  <joint name="joint5" type="revolute">
    <parent link="link5"/>
    <child link="link6"/>
    <origin rpy="0 0 0" xyz="0.0 0.0 0.0595"/>
    <axis xyz="0 1 0"/>
    <limit effort="1" lower="-1.9792033717615696" upper="2.1048670779051615" velocity="4.8"/>
  </joint>
  <transmission name="tran5">
    <type>transmission_interface/SimpleTransmission</type>
    <joint name="joint5">
      <hardwareInterface>hardware_interface/PositionJointInterface</hardwareInterface>
    </joint>
    <actuator name="motor5">
      <hardwareInterface>hardware_interface/PositionJointInterface</hardwareInterface>
      <mechanicalReduction>1</mechanicalReduction>
    </actuator>
  </transmission>
  <!--  Link 6 -->
  <link name="link6">
    <visual>
      <origin rpy="0 0 0" xyz="0 0 0.0"/>
      <geometry>
        <mesh filename="package://robomaster_om_description/meshes/STL/chain_link6.stl" scale="0.001 0.001 0.001"/>
      </geometry>
      <material name="grey"/>
    </visual>
    <collision>
      <origin rpy="0 0 0" xyz="0 0 0.0"/>
      <geometry>
        <mesh filename="package://robomaster_om_description/meshes/STL/chain_link6.stl" scale="0.001 0.001 0.001"/>
      </geometry>
    </collision>
    <!-- <inertial>
      <origin xyz="0 0 0" />
      <mass value="0.033" />
      <inertia ixx="0.1" ixy="0.0" ixz="0.0"
               iyy="0.1" iyz="0.0"
               izz="0.1" />
    </inertial> -->
    <inertial>
      <origin xyz="4.4206755e-02 3.6839985e-07 8.9142216e-03"/>
      <mass value="1.4327573e-01"/>
      <inertia ixx="8.0870749e-05" ixy="0.0" ixz="-1.0157896e-06" iyy="7.5980465e-05" iyz="0.0" izz="9.3127351e-05"/>
    </inertial>
  </link>
  <!--  Joint 6 -->
  <joint name="joint6" type="revolute">
    <parent link="link6"/>
    <child link="link7"/>
    <origin rpy="0 0 0" xyz="0.0 0.0 0.0475"/>
    <axis xyz="0 0 1"/>
    <limit effort="1" lower="-2.827433388230814" upper="2.827433388230814" velocity="4.8"/>
  </joint>
  <transmission name="tran6">
    <type>transmission_interface/SimpleTransmission</type>
    <joint name="joint6">
      <hardwareInterface>hardware_interface/PositionJointInterface</hardwareInterface>
    </joint>
    <actuator name="motor6">
      <hardwareInterface>hardware_interface/PositionJointInterface</hardwareInterface>
      <mechanicalReduction>1</mechanicalReduction>
    </actuator>
  </transmission>
  <!--  Link 7 -->
  <link name="link7">
    <visual>
      <origin rpy="0 0 0" xyz="0 0 0.0"/>
      <geometry>
        <mesh filename="package://robomaster_om_description/meshes/STL/chain_link7.stl" scale="0.001 0.001 0.001"/>
      </geometry>
      <material name="grey"/>
    </visual>
    <collision>
      <origin rpy="0 0 0" xyz="0 0 0.0"/>
      <geometry>
        <mesh filename="package://robomaster_om_description/meshes/STL/chain_link7.stl" scale="0.001 0.001 0.001"/>
      </geometry>
    </collision>
    <!-- <inertial>
      <origin xyz="0 0 0" />
      <mass value="0.228" />
      <inertia ixx="0.1" ixy="0.0" ixz="0.0"
               iyy="0.1" iyz="0.0"
               izz="0.1" />
    </inertial> -->
    <inertial>
      <origin xyz="4.4206755e-02 3.6839985e-07 8.9142216e-03"/>
      <mass value="1.4327573e-01"/>
      <inertia ixx="8.0870749e-05" ixy="0.0" ixz="-1.0157896e-06" iyy="7.5980465e-05" iyz="0.0" izz="9.3127351e-05"/>
    </inertial>
  </link>
  <!--  Gripper link -->
  <link name="gripper_link">
    <visual>
      <origin rpy="0 0 0" xyz="0.0 0.0 0"/>
      <geometry>
        <mesh filename="package://robomaster_om_description/meshes/STL/chain_link_grip_l.stl" scale="0.001 0.001 0.001"/>
      </geometry>
      <material name="grey"/>
    </visual>
    <collision>
      <origin rpy="0 0 0" xyz="0.0 0.0 0"/>
      <geometry>
        <mesh filename="package://robomaster_om_description/meshes/STL/chain_link_grip_l.stl" scale="0.001 0.001 0.001"/>
      </geometry>
    </collision>
    <!-- <inertial>
      <origin xyz="0 0 0" />
      <mass value="0.017" />
      <inertia ixx="1.0e-03" ixy="0.0" ixz="0.0"
               iyy="1.0e-03" iyz="0.0"
               izz="1.0e-03" />
    </inertial> -->
    <inertial>
      <origin xyz="0.0363720668 0.034569616 -4.2836895e-07"/>
      <mass value="3.2218127e-02"/>
      <inertia ixx="9.5568826e-06" ixy="2.8424644e-06" ixz="-3.2829197e-10" iyy="2.2552871e-05" iyz="-3.1463634e-10" izz="1.7605306e-05"/>
    </inertial>
  </link>
  <!--  Gripper joint -->
  <joint name="gripper" type="prismatic">
    <parent link="link7"/>
    <child link="gripper_link"/>
    <origin rpy="0 0 0" xyz="0.0 0.021 0.0707"/>
    <axis xyz="0 1 0"/>
    <limit effort="1" lower="-0.010" upper="0.019" velocity="4.8"/>
  </joint>
  <transmission name="tran7">
    <type>transmission_interface/SimpleTransmission</type>
    <joint name="gripper">
      <hardwareInterface>hardware_interface/PositionJointInterface</hardwareInterface>
    </joint>
    <actuator name="motor7">
      <hardwareInterface>hardware_interface/PositionJointInterface</hardwareInterface>
      <mechanicalReduction>1</mechanicalReduction>
    </actuator>
  </transmission>
  <!--  Gripper link sub -->
  <link name="gripper_link_sub">
    <visual>
      <origin rpy="0 0 0" xyz="0.0 -0.0 0"/>
      <geometry>
        <mesh filename="package://robomaster_om_description/meshes/STL/chain_link_grip_r.stl" scale="0.001 0.001 0.001"/>
      </geometry>
      <material name="grey"/>
    </visual>
    <collision>
      <origin rpy="0 0 0" xyz="0.0 -0.0 0"/>
      <geometry>
        <mesh filename="package://robomaster_om_description/meshes/STL/chain_link_grip_r.stl" scale="0.001 0.001 0.001"/>
      </geometry>
    </collision>
    <!-- <inertial>
      <origin xyz="0 0 0" />
      <mass value="0.017" />
      <inertia ixx="1.0e-03" ixy="0.0" ixz="0.0"
               iyy="1.0e-03" iyz="0.0"
               izz="1.0e-03" />
    </inertial> -->
    <inertial>
      <origin xyz="0.0363720668 -0.034569616 -4.2836895e-07"/>
      <mass value="3.2218127e-02"/>
      <inertia ixx="9.5568826e-06" ixy="2.8424644e-06" ixz="-3.2829197e-10" iyy="2.2552871e-05" iyz="-3.1463634e-10" izz="1.7605306e-05"/>
    </inertial>
  </link>
  <!--  Gripper joint sub -->
  <joint name="gripper_sub" type="prismatic">
    <parent link="link7"/>
    <child link="gripper_link_sub"/>
    <origin rpy="0 0 0" xyz="0.0 -0.021 0.0707"/>
    <axis xyz="0 -1 0"/>
    <limit effort="1" lower="-0.010" upper="0.019" velocity="4.8"/>
    <mimic joint="gripper" multiplier="1"/>
  </joint>
  <transmission name="tran8">
    <type>transmission_interface/SimpleTransmission</type>
    <joint name="gripper_sub">
      <hardwareInterface>hardware_interface/PositionJointInterface</hardwareInterface>
    </joint>
    <actuator name="motor8">
      <hardwareInterface>hardware_interface/PositionJointInterface</hardwareInterface>
      <mechanicalReduction>1</mechanicalReduction>
    </actuator>
  </transmission>
  <!-- end effector joint -->
  <joint name="end_effector_joint" type="fixed">
    <origin rpy="0 0 0" xyz="0.0 0.0 0.115"/>
    <parent link="link7"/>
    <child link="end_effector_link"/>
  </joint>
  <!-- end effector link -->
  <link name="end_effector_link">
    <visual>
      <origin rpy="0 0 0" xyz="0 0 0"/>
      <geometry>
        <box size="0.01 0.01 0.01"/>
      </geometry>
      <material name="red"/>
    </visual>
    <inertial>
      <origin rpy="0 0 0" xyz="0.0 0.0 0.0"/>
      <mass value="0.001"/>
      <inertia ixx="1.0e-06" ixy="0.0" ixz="0.0" iyy="1.0e-06" iyz="0.0" izz="1.0e-06"/>
    </inertial>
  </link>
  <!-- COLOR -->
  <!-- <material name="white">
        <color rgba="1 1 1 1" />
    </material>

    <material name="blue">
        <color rgba="0 0 1 1"/>
    </material>

    <material name="black">
        <color rgba="0 0 0 1"/>
    </material>

    <material name="red">
        <color rgba="1 0 0 1"/>
    </material> -->
  <!-- =============== Link & Joint =============== -->
  <!-- Base -->
  <!-- base_footprint 링크 정의 -->
  <!-- <link name="base_footprint"/> -->
  <!-- base_footprint를 world에 고정 연결 -->
  <!-- <joint name="world_to_base_footprint" type="fixed">
  <parent link="world"/>
  <child link="base_footprint"/>
  <origin xyz="0 0 0" rpy="0 0 0"/>
</joint> -->
  <!-- base_link를 base_v0 매크로로 생성하고 world에 고정 연결 -->
  <!-- <xacro:base_v0 parent="world">
  <origin xyz="0 0 0" rpy="0 0 0"/>
</xacro:base_v0> -->
  <joint name="right_front_wheel_joint" type="continuous">
    <origin xyz="0.0385 -0.1826 -0.0345"/>
    <parent link="base_link"/>
    <child link="right_front_wheel_link"/>
    <limit effort="100" velocity="100"/>
    <axis xyz="0 1 0"/>
  </joint>
  <link name="right_front_wheel_link">
    <visual>
      <geometry>
        <mesh filename="package://robomaster_om_description/meshes/DAE/wheel/wheel_link.dae"/>
      </geometry>
    </visual>
    <collision>
      <geometry>
        <mesh filename="package://robomaster_om_description/meshes/STL/mecanum_wheel/mecanum_wheel.stl"/>
      </geometry>
    </collision>
    <inertial>
      <origin xyz="0.0 -0.011 -0.0"/>
      <mass value="0.25"/>
      <inertia ixx="0.00031" ixy="0" ixz="0" iyy="0.0005" iyz="0" izz="0.00031"/>
    </inertial>
    <surface>
      <friction>
        <ode>
          <mu1>1.2</mu1>
          <mu2>1.2</mu2>
          <kp>1e15</kp>
          <kd>1e13</kd>
        </ode>
      </friction>
      <bounce>
        <restitution_coefficient>0.01</restitution_coefficient>
        <threshold>0</threshold>
      </bounce>
      <contact>
        <ode>
          <max_vel>10</max_vel>
        </ode>
      </contact>
    </surface>
  </link>
  <joint name="r1_RF_roller_joint" type="continuous">
    <origin rpy="-0.0698 -0.00524 0.7854" xyz="-0.006546 -0.0143 0.066466"/>
    <parent link="right_front_wheel_link"/>
    <child link="r1_RF_roller_link"/>
    <axis xyz="0 1 0"/>
  </joint>
  <link name="r1_RF_roller_link">
    <visual>
      <geometry>
        <mesh filename="package://robomaster_om_description/meshes/DAE/roller/roller.dae"/>
      </geometry>
    </visual>
    <collision>
      <geometry>
        <mesh filename="package://robomaster_om_description/meshes/STL/roller/roller.stl"/>
      </geometry>
    </collision>
    <inertial>
      <origin xyz="0.0 0.0 0.0"/>
      <mass value="0.009"/>
      <inertia ixx="0.000001257" ixy="0" ixz="0" iyy="0.000000342" iyz="0" izz="0.000001257"/>
    </inertial>
    <surface>
      <friction>
        <ode>
          <mu1>1.2</mu1>
          <mu2>1.2</mu2>
          <kp>1e15</kp>
          <kd>1e13</kd>
        </ode>
      </friction>
      <bounce>
        <restitution_coefficient>0.01</restitution_coefficient>
        <threshold>0</threshold>
      </bounce>
      <contact>
        <ode>
          <max_vel>10</max_vel>
        </ode>
      </contact>
    </surface>
  </link>
  <joint name="r2_RF_roller_joint" type="continuous">
    <origin rpy="-0.342 -0.1117 0.7854" xyz="-0.031483 -0.0143 0.058902"/>
    <parent link="right_front_wheel_link"/>
    <child link="r2_RF_roller_link"/>
    <axis xyz="0 1 0"/>
  </joint>
  <link name="r2_RF_roller_link">
    <visual>
      <geometry>
        <mesh filename="package://robomaster_om_description/meshes/DAE/roller/roller.dae"/>
      </geometry>
    </visual>
    <collision>
      <geometry>
        <mesh filename="package://robomaster_om_description/meshes/STL/roller/roller.stl"/>
      </geometry>
    </collision>
    <inertial>
      <origin xyz="0.0 0.0 0.0"/>
      <mass value="0.009"/>
      <inertia ixx="0.000001257" ixy="0" ixz="0" iyy="0.000000342" iyz="0" izz="0.000001257"/>
    </inertial>
    <surface>
      <friction>
        <ode>
          <mu1>1.2</mu1>
          <mu2>1.2</mu2>
          <kp>1e15</kp>
          <kd>1e13</kd>
        </ode>
      </friction>
      <bounce>
        <restitution_coefficient>0.01</restitution_coefficient>
        <threshold>0</threshold>
      </bounce>
      <contact>
        <ode>
          <max_vel>10</max_vel>
        </ode>
      </contact>
    </surface>
  </link>
  <joint name="r3_RF_roller_joint" type="continuous">
    <origin rpy="-0.5777 -0.3194 0.7854" xyz="-0.051628 -0.0143 0.04237"/>
    <parent link="right_front_wheel_link"/>
    <child link="r3_RF_roller_link"/>
    <axis xyz="0 1 0"/>
  </joint>
  <link name="r3_RF_roller_link">
    <visual>
      <geometry>
        <mesh filename="package://robomaster_om_description/meshes/DAE/roller/roller.dae"/>
      </geometry>
    </visual>
    <collision>
      <geometry>
        <mesh filename="package://robomaster_om_description/meshes/STL/roller/roller.stl"/>
      </geometry>
    </collision>
    <inertial>
      <origin xyz="0.0 0.0 0.0"/>
      <mass value="0.009"/>
      <inertia ixx="0.000001257" ixy="0" ixz="0" iyy="0.000000342" iyz="0" izz="0.000001257"/>
    </inertial>
    <surface>
      <friction>
        <ode>
          <mu1>1.2</mu1>
          <mu2>1.2</mu2>
          <kp>1e15</kp>
          <kd>1e13</kd>
        </ode>
      </friction>
      <bounce>
        <restitution_coefficient>0.01</restitution_coefficient>
        <threshold>0</threshold>
      </bounce>
      <contact>
        <ode>
          <max_vel>10</max_vel>
        </ode>
      </contact>
    </surface>
  </link>
  <joint name="r4_RE_roller_joint" type="continuous">
    <origin rpy="-0.82 -0.52 0.7854" xyz="-0.063912 -0.0143 0.019388"/>
    <parent link="right_front_wheel_link"/>
    <child link="r4_RE_roller_link"/>
    <axis xyz="0 1 0"/>
  </joint>
  <link name="r4_RE_roller_link">
    <visual>
      <geometry>
        <mesh filename="package://robomaster_om_description/meshes/DAE/roller/roller.dae"/>
      </geometry>
    </visual>
    <collision>
      <geometry>
        <mesh filename="package://robomaster_om_description/meshes/STL/roller/roller.stl"/>
      </geometry>
    </collision>
    <inertial>
      <origin xyz="0.0 0.0 0.0"/>
      <mass value="0.009"/>
      <inertia ixx="0.000001257" ixy="0" ixz="0" iyy="0.000000342" iyz="0" izz="0.000001257"/>
    </inertial>
    <surface>
      <friction>
        <ode>
          <mu1>1.2</mu1>
          <mu2>1.2</mu2>
          <kp>1e15</kp>
          <kd>1e13</kd>
        </ode>
      </friction>
      <bounce>
        <restitution_coefficient>0.01</restitution_coefficient>
        <threshold>0</threshold>
      </bounce>
      <contact>
        <ode>
          <max_vel>10</max_vel>
        </ode>
      </contact>
    </surface>
  </link>
  <joint name="r5_RF_roller_joint" type="continuous">
    <origin rpy="-1.08 -0.62 0.7854" xyz="-0.066466 -0.0143 -0.006546"/>
    <parent link="right_front_wheel_link"/>
    <child link="r5_RF_roller_link"/>
    <axis xyz="0 1 0"/>
  </joint>
  <link name="r5_RF_roller_link">
    <visual>
      <geometry>
        <mesh filename="package://robomaster_om_description/meshes/DAE/roller/roller.dae"/>
      </geometry>
    </visual>
    <collision>
      <geometry>
        <mesh filename="package://robomaster_om_description/meshes/STL/roller/roller.stl"/>
      </geometry>
    </collision>
    <inertial>
      <origin xyz="0.0 0.0 0.0"/>
      <mass value="0.009"/>
      <inertia ixx="0.000001257" ixy="0" ixz="0" iyy="0.000000342" iyz="0" izz="0.000001257"/>
    </inertial>
    <surface>
      <friction>
        <ode>
          <mu1>1.2</mu1>
          <mu2>1.2</mu2>
          <kp>1e15</kp>
          <kd>1e13</kd>
        </ode>
      </friction>
      <bounce>
        <restitution_coefficient>0.01</restitution_coefficient>
        <threshold>0</threshold>
      </bounce>
      <contact>
        <ode>
          <max_vel>10</max_vel>
        </ode>
      </contact>
    </surface>
  </link>
  <joint name="r6_RF_roller_joint" type="continuous">
    <origin rpy="-1.28 -0.82 0.7854" xyz="-0.058902 -0.0143 -0.031483"/>
    <parent link="right_front_wheel_link"/>
    <child link="r6_RF_roller_link"/>
    <axis xyz="0 1 0"/>
  </joint>
  <link name="r6_RF_roller_link">
    <visual>
      <geometry>
        <mesh filename="package://robomaster_om_description/meshes/DAE/roller/roller.dae"/>
      </geometry>
    </visual>
    <collision>
      <geometry>
        <mesh filename="package://robomaster_om_description/meshes/STL/roller/roller.stl"/>
      </geometry>
    </collision>
    <inertial>
      <origin xyz="0.0 0.0 0.0"/>
      <mass value="0.009"/>
      <inertia ixx="0.000001257" ixy="0" ixz="0" iyy="0.000000342" iyz="0" izz="0.000001257"/>
    </inertial>
    <surface>
      <friction>
        <ode>
          <mu1>1.2</mu1>
          <mu2>1.2</mu2>
          <kp>1e15</kp>
          <kd>1e13</kd>
        </ode>
      </friction>
      <bounce>
        <restitution_coefficient>0.01</restitution_coefficient>
        <threshold>0</threshold>
      </bounce>
      <contact>
        <ode>
          <max_vel>10</max_vel>
        </ode>
      </contact>
    </surface>
  </link>
  <joint name="r7_RF_roller_joint" type="continuous">
    <origin rpy="-1.44 -1.1 0.7854" xyz="-0.04237 -0.0143 -0.051628"/>
    <parent link="right_front_wheel_link"/>
    <child link="r7_RF_roller_link"/>
    <axis xyz="0 1 0"/>
  </joint>
  <link name="r7_RF_roller_link">
    <visual>
      <geometry>
        <mesh filename="package://robomaster_om_description/meshes/DAE/roller/roller.dae"/>
      </geometry>
    </visual>
    <collision>
      <geometry>
        <mesh filename="package://robomaster_om_description/meshes/STL/roller/roller.stl"/>
      </geometry>
    </collision>
    <inertial>
      <origin xyz="0.0 0.0 0.0"/>
      <mass value="0.009"/>
      <inertia ixx="0.000001257" ixy="0" ixz="0" iyy="0.000000342" iyz="0" izz="0.000001257"/>
    </inertial>
    <surface>
      <friction>
        <ode>
          <mu1>1.2</mu1>
          <mu2>1.2</mu2>
          <kp>1e15</kp>
          <kd>1e13</kd>
        </ode>
      </friction>
      <bounce>
        <restitution_coefficient>0.01</restitution_coefficient>
        <threshold>0</threshold>
      </bounce>
      <contact>
        <ode>
          <max_vel>10</max_vel>
        </ode>
      </contact>
    </surface>
  </link>
  <joint name="r8_RF_roller_joint" type="continuous">
    <origin rpy="-1.56 -1.36 0.7854" xyz="-0.019388 -0.0143 -0.063912"/>
    <parent link="right_front_wheel_link"/>
    <child link="r8_RF_roller_link"/>
    <axis xyz="0 1 0"/>
  </joint>
  <link name="r8_RF_roller_link">
    <visual>
      <geometry>
        <mesh filename="package://robomaster_om_description/meshes/DAE/roller/roller.dae"/>
      </geometry>
    </visual>
    <collision>
      <geometry>
        <mesh filename="package://robomaster_om_description/meshes/STL/roller/roller.stl"/>
      </geometry>
    </collision>
    <inertial>
      <origin xyz="0.0 0.0 0.0"/>
      <mass value="0.009"/>
      <inertia ixx="0.000001257" ixy="0" ixz="0" iyy="0.000000342" iyz="0" izz="0.000001257"/>
    </inertial>
    <surface>
      <friction>
        <ode>
          <mu1>1.2</mu1>
          <mu2>1.2</mu2>
          <kp>1e15</kp>
          <kd>1e13</kd>
        </ode>
      </friction>
      <bounce>
        <restitution_coefficient>0.01</restitution_coefficient>
        <threshold>0</threshold>
      </bounce>
      <contact>
        <ode>
          <max_vel>10</max_vel>
        </ode>
      </contact>
    </surface>
  </link>
  <joint name="r9_RF_roller_joint" type="continuous">
    <origin rpy="0.0698 -0.00524 -0.7854" xyz="0.006546 -0.0143 -0.066466"/>
    <parent link="right_front_wheel_link"/>
    <child link="r9_RF_roller_link"/>
    <axis xyz="0 1 0"/>
  </joint>
  <link name="r9_RF_roller_link">
    <visual>
      <geometry>
        <mesh filename="package://robomaster_om_description/meshes/DAE/roller/roller.dae"/>
      </geometry>
    </visual>
    <collision>
      <geometry>
        <mesh filename="package://robomaster_om_description/meshes/STL/roller/roller.stl"/>
      </geometry>
    </collision>
    <inertial>
      <origin xyz="0.0 0.0 0.0"/>
      <mass value="0.009"/>
      <inertia ixx="0.000001257" ixy="0" ixz="0" iyy="0.000000342" iyz="0" izz="0.000001257"/>
    </inertial>
    <surface>
      <friction>
        <ode>
          <mu1>1.2</mu1>
          <mu2>1.2</mu2>
          <kp>1e15</kp>
          <kd>1e13</kd>
        </ode>
      </friction>
      <bounce>
        <restitution_coefficient>0.01</restitution_coefficient>
        <threshold>0</threshold>
      </bounce>
      <contact>
        <ode>
          <max_vel>10</max_vel>
        </ode>
      </contact>
    </surface>
  </link>
  <joint name="r10_RF_roller_joint" type="continuous">
    <origin rpy="0.342 -0.1117 -0.7854" xyz="0.031483 -0.0143 -0.058902"/>
    <parent link="right_front_wheel_link"/>
    <child link="r10_RF_roller_link"/>
    <axis xyz="0 1 0"/>
  </joint>
  <link name="r10_RF_roller_link">
    <visual>
      <geometry>
        <mesh filename="package://robomaster_om_description/meshes/DAE/roller/roller.dae"/>
      </geometry>
    </visual>
    <collision>
      <geometry>
        <mesh filename="package://robomaster_om_description/meshes/STL/roller/roller.stl"/>
      </geometry>
    </collision>
    <inertial>
      <origin xyz="0.0 0.0 0.0"/>
      <mass value="0.009"/>
      <inertia ixx="0.000001257" ixy="0" ixz="0" iyy="0.000000342" iyz="0" izz="0.000001257"/>
    </inertial>
    <surface>
      <friction>
        <ode>
          <mu1>1.2</mu1>
          <mu2>1.2</mu2>
          <kp>1e15</kp>
          <kd>1e13</kd>
        </ode>
      </friction>
      <bounce>
        <restitution_coefficient>0.01</restitution_coefficient>
        <threshold>0</threshold>
      </bounce>
      <contact>
        <ode>
          <max_vel>10</max_vel>
        </ode>
      </contact>
    </surface>
  </link>
  <joint name="r11_RF_roller_joint" type="continuous">
    <origin rpy="0.5777 -0.3194 -0.7854" xyz="0.051628 -0.0143 -0.04237"/>
    <parent link="right_front_wheel_link"/>
    <child link="r11_RF_roller_link"/>
    <axis xyz="0 1 0"/>
  </joint>
  <link name="r11_RF_roller_link">
    <visual>
      <geometry>
        <mesh filename="package://robomaster_om_description/meshes/DAE/roller/roller.dae"/>
      </geometry>
    </visual>
    <collision>
      <geometry>
        <mesh filename="package://robomaster_om_description/meshes/STL/roller/roller.stl"/>
      </geometry>
    </collision>
    <inertial>
      <origin xyz="0.0 0.0 0.0"/>
      <mass value="0.009"/>
      <inertia ixx="0.000001257" ixy="0" ixz="0" iyy="0.000000342" iyz="0" izz="0.000001257"/>
    </inertial>
    <surface>
      <friction>
        <ode>
          <mu1>1.2</mu1>
          <mu2>1.2</mu2>
          <kp>1e15</kp>
          <kd>1e13</kd>
        </ode>
      </friction>
      <bounce>
        <restitution_coefficient>0.01</restitution_coefficient>
        <threshold>0</threshold>
      </bounce>
      <contact>
        <ode>
          <max_vel>10</max_vel>
        </ode>
      </contact>
    </surface>
  </link>
  <joint name="r12_RF_roller_joint" type="continuous">
    <origin rpy="0.82 -0.52 -0.7854" xyz="0.063912 -0.0143 -0.019388"/>
    <parent link="right_front_wheel_link"/>
    <child link="r12_RF_roller_link"/>
    <axis xyz="0 1 0"/>
  </joint>
  <link name="r12_RF_roller_link">
    <visual>
      <geometry>
        <mesh filename="package://robomaster_om_description/meshes/DAE/roller/roller.dae"/>
      </geometry>
    </visual>
    <collision>
      <geometry>
        <mesh filename="package://robomaster_om_description/meshes/STL/roller/roller.stl"/>
      </geometry>
    </collision>
    <inertial>
      <origin xyz="0.0 0.0 0.0"/>
      <mass value="0.009"/>
      <inertia ixx="0.000001257" ixy="0" ixz="0" iyy="0.000000342" iyz="0" izz="0.000001257"/>
    </inertial>
    <surface>
      <friction>
        <ode>
          <mu1>1.2</mu1>
          <mu2>1.2</mu2>
          <kp>1e15</kp>
          <kd>1e13</kd>
        </ode>
      </friction>
      <bounce>
        <restitution_coefficient>0.01</restitution_coefficient>
        <threshold>0</threshold>
      </bounce>
      <contact>
        <ode>
          <max_vel>10</max_vel>
        </ode>
      </contact>
    </surface>
  </link>
  <joint name="r13_RF_roller_joint" type="continuous">
    <origin rpy="1.08 -0.62 -0.7854" xyz="0.066466 -0.0143 0.006546"/>
    <parent link="right_front_wheel_link"/>
    <child link="r13_RF_roller_link"/>
    <axis xyz="0 1 0"/>
  </joint>
  <link name="r13_RF_roller_link">
    <visual>
      <geometry>
        <mesh filename="package://robomaster_om_description/meshes/DAE/roller/roller.dae"/>
      </geometry>
    </visual>
    <collision>
      <geometry>
        <mesh filename="package://robomaster_om_description/meshes/STL/roller/roller.stl"/>
      </geometry>
    </collision>
    <inertial>
      <origin xyz="0.0 0.0 0.0"/>
      <mass value="0.009"/>
      <inertia ixx="0.000001257" ixy="0" ixz="0" iyy="0.000000342" iyz="0" izz="0.000001257"/>
    </inertial>
    <surface>
      <friction>
        <ode>
          <mu1>1.2</mu1>
          <mu2>1.2</mu2>
          <kp>1e15</kp>
          <kd>1e13</kd>
        </ode>
      </friction>
      <bounce>
        <restitution_coefficient>0.01</restitution_coefficient>
        <threshold>0</threshold>
      </bounce>
      <contact>
        <ode>
          <max_vel>10</max_vel>
        </ode>
      </contact>
    </surface>
  </link>
  <joint name="r14_RF_roller_joint" type="continuous">
    <origin rpy="1.28 -0.82 -0.7854" xyz="0.058902 -0.0143 0.031483"/>
    <parent link="right_front_wheel_link"/>
    <child link="r14_RF_roller_link"/>
    <axis xyz="0 1 0"/>
  </joint>
  <link name="r14_RF_roller_link">
    <visual>
      <geometry>
        <mesh filename="package://robomaster_om_description/meshes/DAE/roller/roller.dae"/>
      </geometry>
    </visual>
    <collision>
      <geometry>
        <mesh filename="package://robomaster_om_description/meshes/STL/roller/roller.stl"/>
      </geometry>
    </collision>
    <inertial>
      <origin xyz="0.0 0.0 0.0"/>
      <mass value="0.009"/>
      <inertia ixx="0.000001257" ixy="0" ixz="0" iyy="0.000000342" iyz="0" izz="0.000001257"/>
    </inertial>
    <surface>
      <friction>
        <ode>
          <mu1>1.2</mu1>
          <mu2>1.2</mu2>
          <kp>1e15</kp>
          <kd>1e13</kd>
        </ode>
      </friction>
      <bounce>
        <restitution_coefficient>0.01</restitution_coefficient>
        <threshold>0</threshold>
      </bounce>
      <contact>
        <ode>
          <max_vel>10</max_vel>
        </ode>
      </contact>
    </surface>
  </link>
  <joint name="r15_RF_roller_joint" type="continuous">
    <origin rpy="1.44 -1.1 -0.7854" xyz="0.04237 -0.0143 0.051628"/>
    <parent link="right_front_wheel_link"/>
    <child link="r15_RF_roller_link"/>
    <axis xyz="0 1 0"/>
  </joint>
  <link name="r15_RF_roller_link">
    <visual>
      <geometry>
        <mesh filename="package://robomaster_om_description/meshes/DAE/roller/roller.dae"/>
      </geometry>
    </visual>
    <collision>
      <geometry>
        <mesh filename="package://robomaster_om_description/meshes/STL/roller/roller.stl"/>
      </geometry>
    </collision>
    <inertial>
      <origin xyz="0.0 0.0 0.0"/>
      <mass value="0.009"/>
      <inertia ixx="0.000001257" ixy="0" ixz="0" iyy="0.000000342" iyz="0" izz="0.000001257"/>
    </inertial>
    <surface>
      <friction>
        <ode>
          <mu1>1.2</mu1>
          <mu2>1.2</mu2>
          <kp>1e15</kp>
          <kd>1e13</kd>
        </ode>
      </friction>
      <bounce>
        <restitution_coefficient>0.01</restitution_coefficient>
        <threshold>0</threshold>
      </bounce>
      <contact>
        <ode>
          <max_vel>10</max_vel>
        </ode>
      </contact>
    </surface>
  </link>
  <joint name="r16_RF_roller_joint" type="continuous">
    <origin rpy="1.56 -1.36 -0.7854" xyz="0.019388 -0.0143 0.063912"/>
    <parent link="right_front_wheel_link"/>
    <child link="r16_RF_roller_link"/>
    <axis xyz="0 1 0"/>
  </joint>
  <link name="r16_RF_roller_link">
    <visual>
      <geometry>
        <mesh filename="package://robomaster_om_description/meshes/DAE/roller/roller.dae"/>
      </geometry>
    </visual>
    <collision>
      <geometry>
        <mesh filename="package://robomaster_om_description/meshes/STL/roller/roller.stl"/>
      </geometry>
    </collision>
    <inertial>
      <origin xyz="0.0 0.0 0.0"/>
      <mass value="0.009"/>
      <inertia ixx="0.000001257" ixy="0" ixz="0" iyy="0.000000342" iyz="0" izz="0.000001257"/>
    </inertial>
    <surface>
      <friction>
        <ode>
          <mu1>1.2</mu1>
          <mu2>1.2</mu2>
          <kp>1e15</kp>
          <kd>1e13</kd>
        </ode>
      </friction>
      <bounce>
        <restitution_coefficient>0.01</restitution_coefficient>
        <threshold>0</threshold>
      </bounce>
      <contact>
        <ode>
          <max_vel>10</max_vel>
        </ode>
      </contact>
    </surface>
  </link>
  <joint name="left_front_wheel_joint" type="continuous">
    <origin rpy="0 0 3.14159274" xyz="0.0385 0.1826 -0.0345"/>
    <parent link="base_link"/>
    <child link="left_front_wheel_link"/>
    <limit effort="100" velocity="100"/>
    <axis xyz="0 -1 0"/>
  </joint>
  <link name="left_front_wheel_link">
    <visual>
      <geometry>
        <mesh filename="package://robomaster_om_description/meshes/DAE/wheel/wheel_link.dae"/>
      </geometry>
    </visual>
    <collision>
      <geometry>
        <mesh filename="package://robomaster_om_description/meshes/STL/mecanum_wheel/mecanum_wheel.stl"/>
      </geometry>
    </collision>
    <inertial>
      <origin xyz="0.0 -0.011 -0.0"/>
      <mass value="0.25"/>
      <inertia ixx="0.00031" ixy="0" ixz="0" iyy="0.0005" iyz="0" izz="0.00031"/>
    </inertial>
    <surface>
      <friction>
        <ode>
          <mu1>1.2</mu1>
          <mu2>1.2</mu2>
          <kp>1e15</kp>
          <kd>1e13</kd>
        </ode>
      </friction>
      <bounce>
        <restitution_coefficient>0.01</restitution_coefficient>
        <threshold>0</threshold>
      </bounce>
      <contact>
        <ode>
          <max_vel>10</max_vel>
        </ode>
      </contact>
    </surface>
  </link>
  <joint name="r1_LF_roller_joint" type="continuous">
    <origin rpy="-0.0698 -0.00524 -0.7854" xyz="0.006546 -0.0143 0.066466"/>
    <parent link="left_front_wheel_link"/>
    <child link="r1_LF_roller_link"/>
    <axis xyz="0 1 0"/>
  </joint>
  <link name="r1_LF_roller_link">
    <visual>
      <geometry>
        <mesh filename="package://robomaster_om_description/meshes/DAE/roller/roller.dae"/>
      </geometry>
    </visual>
    <collision>
      <geometry>
        <mesh filename="package://robomaster_om_description/meshes/STL/roller/roller.stl"/>
      </geometry>
    </collision>
    <inertial>
      <origin xyz="0.0 0.0 0.0"/>
      <mass value="0.009"/>
      <inertia ixx="0.000001257" ixy="0" ixz="0" iyy="0.000000342" iyz="0" izz="0.000001257"/>
    </inertial>
    <surface>
      <friction>
        <ode>
          <mu1>1.2</mu1>
          <mu2>1.2</mu2>
          <kp>1e15</kp>
          <kd>1e13</kd>
        </ode>
      </friction>
      <bounce>
        <restitution_coefficient>0.01</restitution_coefficient>
        <threshold>0</threshold>
      </bounce>
      <contact>
        <ode>
          <max_vel>10</max_vel>
        </ode>
      </contact>
    </surface>
  </link>
  <joint name="r2_LF_roller_joint" type="continuous">
    <origin rpy="-1.56 -1.26 0.7854" xyz="0.031483 -0.0143 0.058902"/>
    <parent link="left_front_wheel_link"/>
    <child link="r2_LF_roller_link"/>
    <axis xyz="0 1 0"/>
  </joint>
  <link name="r2_LF_roller_link">
    <visual>
      <geometry>
        <mesh filename="package://robomaster_om_description/meshes/DAE/roller/roller.dae"/>
      </geometry>
    </visual>
    <collision>
      <geometry>
        <mesh filename="package://robomaster_om_description/meshes/STL/roller/roller.stl"/>
      </geometry>
    </collision>
    <inertial>
      <origin xyz="0.0 0.0 0.0"/>
      <mass value="0.009"/>
      <inertia ixx="0.000001257" ixy="0" ixz="0" iyy="0.000000342" iyz="0" izz="0.000001257"/>
    </inertial>
    <surface>
      <friction>
        <ode>
          <mu1>1.2</mu1>
          <mu2>1.2</mu2>
          <kp>1e15</kp>
          <kd>1e13</kd>
        </ode>
      </friction>
      <bounce>
        <restitution_coefficient>0.01</restitution_coefficient>
        <threshold>0</threshold>
      </bounce>
      <contact>
        <ode>
          <max_vel>10</max_vel>
        </ode>
      </contact>
    </surface>
  </link>
  <joint name="r3_LF_roller_joint" type="continuous">
    <origin rpy="-1.36 -1.04 0.7854" xyz="0.051628 -0.0143 0.04237"/>
    <parent link="left_front_wheel_link"/>
    <child link="r3_LF_roller_link"/>
    <axis xyz="0 1 0"/>
  </joint>
  <link name="r3_LF_roller_link">
    <visual>
      <geometry>
        <mesh filename="package://robomaster_om_description/meshes/DAE/roller/roller.dae"/>
      </geometry>
    </visual>
    <collision>
      <geometry>
        <mesh filename="package://robomaster_om_description/meshes/STL/roller/roller.stl"/>
      </geometry>
    </collision>
    <inertial>
      <origin xyz="0.0 0.0 0.0"/>
      <mass value="0.009"/>
      <inertia ixx="0.000001257" ixy="0" ixz="0" iyy="0.000000342" iyz="0" izz="0.000001257"/>
    </inertial>
    <surface>
      <friction>
        <ode>
          <mu1>1.2</mu1>
          <mu2>1.2</mu2>
          <kp>1e15</kp>
          <kd>1e13</kd>
        </ode>
      </friction>
      <bounce>
        <restitution_coefficient>0.01</restitution_coefficient>
        <threshold>0</threshold>
      </bounce>
      <contact>
        <ode>
          <max_vel>10</max_vel>
        </ode>
      </contact>
    </surface>
  </link>
  <joint name="r4_LF_roller_joint" type="continuous">
    <origin rpy="-1.2 -0.76 0.7854" xyz="0.063912 -0.0143 0.019388"/>
    <parent link="left_front_wheel_link"/>
    <child link="r4_LF_roller_link"/>
    <axis xyz="0 1 0"/>
  </joint>
  <link name="r4_LF_roller_link">
    <visual>
      <geometry>
        <mesh filename="package://robomaster_om_description/meshes/DAE/roller/roller.dae"/>
      </geometry>
    </visual>
    <collision>
      <geometry>
        <mesh filename="package://robomaster_om_description/meshes/STL/roller/roller.stl"/>
      </geometry>
    </collision>
    <inertial>
      <origin xyz="0.0 0.0 0.0"/>
      <mass value="0.009"/>
      <inertia ixx="0.000001257" ixy="0" ixz="0" iyy="0.000000342" iyz="0" izz="0.000001257"/>
    </inertial>
    <surface>
      <friction>
        <ode>
          <mu1>1.2</mu1>
          <mu2>1.2</mu2>
          <kp>1e15</kp>
          <kd>1e13</kd>
        </ode>
      </friction>
      <bounce>
        <restitution_coefficient>0.01</restitution_coefficient>
        <threshold>0</threshold>
      </bounce>
      <contact>
        <ode>
          <max_vel>10</max_vel>
        </ode>
      </contact>
    </surface>
  </link>
  <joint name="r5_LF_roller_joint" type="continuous">
    <origin rpy="-1.0 -0.58 0.7854" xyz="0.066466 -0.0143 -0.006546"/>
    <parent link="left_front_wheel_link"/>
    <child link="r5_LF_roller_link"/>
    <axis xyz="0 1 0"/>
  </joint>
  <link name="r5_LF_roller_link">
    <visual>
      <geometry>
        <mesh filename="package://robomaster_om_description/meshes/DAE/roller/roller.dae"/>
      </geometry>
    </visual>
    <collision>
      <geometry>
        <mesh filename="package://robomaster_om_description/meshes/STL/roller/roller.stl"/>
      </geometry>
    </collision>
    <inertial>
      <origin xyz="0.0 0.0 0.0"/>
      <mass value="0.009"/>
      <inertia ixx="0.000001257" ixy="0" ixz="0" iyy="0.000000342" iyz="0" izz="0.000001257"/>
    </inertial>
    <surface>
      <friction>
        <ode>
          <mu1>1.2</mu1>
          <mu2>1.2</mu2>
          <kp>1e15</kp>
          <kd>1e13</kd>
        </ode>
      </friction>
      <bounce>
        <restitution_coefficient>0.01</restitution_coefficient>
        <threshold>0</threshold>
      </bounce>
      <contact>
        <ode>
          <max_vel>10</max_vel>
        </ode>
      </contact>
    </surface>
  </link>
  <joint name="r6_LF_roller_joint" type="continuous">
    <origin rpy="-0.74 -0.48 0.7854" xyz="0.058902 -0.0143 -0.031483"/>
    <parent link="left_front_wheel_link"/>
    <child link="r6_LF_roller_link"/>
    <axis xyz="0 1 0"/>
  </joint>
  <link name="r6_LF_roller_link">
    <visual>
      <geometry>
        <mesh filename="package://robomaster_om_description/meshes/DAE/roller/roller.dae"/>
      </geometry>
    </visual>
    <collision>
      <geometry>
        <mesh filename="package://robomaster_om_description/meshes/STL/roller/roller.stl"/>
      </geometry>
    </collision>
    <inertial>
      <origin xyz="0.0 0.0 0.0"/>
      <mass value="0.009"/>
      <inertia ixx="0.000001257" ixy="0" ixz="0" iyy="0.000000342" iyz="0" izz="0.000001257"/>
    </inertial>
    <surface>
      <friction>
        <ode>
          <mu1>1.2</mu1>
          <mu2>1.2</mu2>
          <kp>1e15</kp>
          <kd>1e13</kd>
        </ode>
      </friction>
      <bounce>
        <restitution_coefficient>0.01</restitution_coefficient>
        <threshold>0</threshold>
      </bounce>
      <contact>
        <ode>
          <max_vel>10</max_vel>
        </ode>
      </contact>
    </surface>
  </link>
  <joint name="r7_LF_roller_joint" type="continuous">
    <origin rpy="-0.51 -0.3194 0.7854" xyz="0.04237 -0.0143 -0.051628"/>
    <parent link="left_front_wheel_link"/>
    <child link="r7_LF_roller_link"/>
    <axis xyz="0 1 0"/>
  </joint>
  <link name="r7_LF_roller_link">
    <visual>
      <geometry>
        <mesh filename="package://robomaster_om_description/meshes/DAE/roller/roller.dae"/>
      </geometry>
    </visual>
    <collision>
      <geometry>
        <mesh filename="package://robomaster_om_description/meshes/STL/roller/roller.stl"/>
      </geometry>
    </collision>
    <inertial>
      <origin xyz="0.0 0.0 0.0"/>
      <mass value="0.009"/>
      <inertia ixx="0.000001257" ixy="0" ixz="0" iyy="0.000000342" iyz="0" izz="0.000001257"/>
    </inertial>
    <surface>
      <friction>
        <ode>
          <mu1>1.2</mu1>
          <mu2>1.2</mu2>
          <kp>1e15</kp>
          <kd>1e13</kd>
        </ode>
      </friction>
      <bounce>
        <restitution_coefficient>0.01</restitution_coefficient>
        <threshold>0</threshold>
      </bounce>
      <contact>
        <ode>
          <max_vel>10</max_vel>
        </ode>
      </contact>
    </surface>
  </link>
  <joint name="r8_LF_roller_joint" type="continuous">
    <origin rpy="-0.2 -0.1117 0.7854" xyz="0.019388 -0.0143 -0.063912"/>
    <parent link="left_front_wheel_link"/>
    <child link="r8_LF_roller_link"/>
    <axis xyz="0 1 0"/>
  </joint>
  <link name="r8_LF_roller_link">
    <visual>
      <geometry>
        <mesh filename="package://robomaster_om_description/meshes/DAE/roller/roller.dae"/>
      </geometry>
    </visual>
    <collision>
      <geometry>
        <mesh filename="package://robomaster_om_description/meshes/STL/roller/roller.stl"/>
      </geometry>
    </collision>
    <inertial>
      <origin xyz="0.0 0.0 0.0"/>
      <mass value="0.009"/>
      <inertia ixx="0.000001257" ixy="0" ixz="0" iyy="0.000000342" iyz="0" izz="0.000001257"/>
    </inertial>
    <surface>
      <friction>
        <ode>
          <mu1>1.2</mu1>
          <mu2>1.2</mu2>
          <kp>1e15</kp>
          <kd>1e13</kd>
        </ode>
      </friction>
      <bounce>
        <restitution_coefficient>0.01</restitution_coefficient>
        <threshold>0</threshold>
      </bounce>
      <contact>
        <ode>
          <max_vel>10</max_vel>
        </ode>
      </contact>
    </surface>
  </link>
  <joint name="r9_LF_roller_joint" type="continuous">
    <origin rpy="0.0698 -0.00524 0.7854" xyz="-0.006546 -0.0143 -0.066466"/>
    <parent link="left_front_wheel_link"/>
    <child link="r9_LF_roller_link"/>
    <axis xyz="0 1 0"/>
  </joint>
  <link name="r9_LF_roller_link">
    <visual>
      <geometry>
        <mesh filename="package://robomaster_om_description/meshes/DAE/roller/roller.dae"/>
      </geometry>
    </visual>
    <collision>
      <geometry>
        <mesh filename="package://robomaster_om_description/meshes/STL/roller/roller.stl"/>
      </geometry>
    </collision>
    <inertial>
      <origin xyz="0.0 0.0 0.0"/>
      <mass value="0.009"/>
      <inertia ixx="0.000001257" ixy="0" ixz="0" iyy="0.000000342" iyz="0" izz="0.000001257"/>
    </inertial>
    <surface>
      <friction>
        <ode>
          <mu1>1.2</mu1>
          <mu2>1.2</mu2>
          <kp>1e15</kp>
          <kd>1e13</kd>
        </ode>
      </friction>
      <bounce>
        <restitution_coefficient>0.01</restitution_coefficient>
        <threshold>0</threshold>
      </bounce>
      <contact>
        <ode>
          <max_vel>10</max_vel>
        </ode>
      </contact>
    </surface>
  </link>
  <joint name="r10_LF_roller_joint" type="continuous">
    <origin rpy="1.56 -1.26 -0.7854" xyz="-0.031483 -0.0143 -0.058902"/>
    <parent link="left_front_wheel_link"/>
    <child link="r10_LF_roller_link"/>
    <axis xyz="0 1 0"/>
  </joint>
  <link name="r10_LF_roller_link">
    <visual>
      <geometry>
        <mesh filename="package://robomaster_om_description/meshes/DAE/roller/roller.dae"/>
      </geometry>
    </visual>
    <collision>
      <geometry>
        <mesh filename="package://robomaster_om_description/meshes/STL/roller/roller.stl"/>
      </geometry>
    </collision>
    <inertial>
      <origin xyz="0.0 0.0 0.0"/>
      <mass value="0.009"/>
      <inertia ixx="0.000001257" ixy="0" ixz="0" iyy="0.000000342" iyz="0" izz="0.000001257"/>
    </inertial>
    <surface>
      <friction>
        <ode>
          <mu1>1.2</mu1>
          <mu2>1.2</mu2>
          <kp>1e15</kp>
          <kd>1e13</kd>
        </ode>
      </friction>
      <bounce>
        <restitution_coefficient>0.01</restitution_coefficient>
        <threshold>0</threshold>
      </bounce>
      <contact>
        <ode>
          <max_vel>10</max_vel>
        </ode>
      </contact>
    </surface>
  </link>
  <joint name="r11_LF_roller_joint" type="continuous">
    <origin rpy="1.36 -1.04 -0.7854" xyz="-0.051628 -0.0143 -0.04237"/>
    <parent link="left_front_wheel_link"/>
    <child link="r11_LF_roller_link"/>
    <axis xyz="0 1 0"/>
  </joint>
  <link name="r11_LF_roller_link">
    <visual>
      <geometry>
        <mesh filename="package://robomaster_om_description/meshes/DAE/roller/roller.dae"/>
      </geometry>
    </visual>
    <collision>
      <geometry>
        <mesh filename="package://robomaster_om_description/meshes/STL/roller/roller.stl"/>
      </geometry>
    </collision>
    <inertial>
      <origin xyz="0.0 0.0 0.0"/>
      <mass value="0.009"/>
      <inertia ixx="0.000001257" ixy="0" ixz="0" iyy="0.000000342" iyz="0" izz="0.000001257"/>
    </inertial>
    <surface>
      <friction>
        <ode>
          <mu1>1.2</mu1>
          <mu2>1.2</mu2>
          <kp>1e15</kp>
          <kd>1e13</kd>
        </ode>
      </friction>
      <bounce>
        <restitution_coefficient>0.01</restitution_coefficient>
        <threshold>0</threshold>
      </bounce>
      <contact>
        <ode>
          <max_vel>10</max_vel>
        </ode>
      </contact>
    </surface>
  </link>
  <joint name="r12_LF_roller_joint" type="continuous">
    <origin rpy="1.2 -0.76 -0.7854" xyz="-0.063912 -0.0143 -0.019388"/>
    <parent link="left_front_wheel_link"/>
    <child link="r12_LF_roller_link"/>
    <axis xyz="0 1 0"/>
  </joint>
  <link name="r12_LF_roller_link">
    <visual>
      <geometry>
        <mesh filename="package://robomaster_om_description/meshes/DAE/roller/roller.dae"/>
      </geometry>
    </visual>
    <collision>
      <geometry>
        <mesh filename="package://robomaster_om_description/meshes/STL/roller/roller.stl"/>
      </geometry>
    </collision>
    <inertial>
      <origin xyz="0.0 0.0 0.0"/>
      <mass value="0.009"/>
      <inertia ixx="0.000001257" ixy="0" ixz="0" iyy="0.000000342" iyz="0" izz="0.000001257"/>
    </inertial>
    <surface>
      <friction>
        <ode>
          <mu1>1.2</mu1>
          <mu2>1.2</mu2>
          <kp>1e15</kp>
          <kd>1e13</kd>
        </ode>
      </friction>
      <bounce>
        <restitution_coefficient>0.01</restitution_coefficient>
        <threshold>0</threshold>
      </bounce>
      <contact>
        <ode>
          <max_vel>10</max_vel>
        </ode>
      </contact>
    </surface>
  </link>
  <joint name="r13_LF_roller_joint" type="continuous">
    <origin rpy="1.0 -0.58 -0.7854" xyz="-0.066466 -0.0143 0.006546"/>
    <parent link="left_front_wheel_link"/>
    <child link="r13_LF_roller_link"/>
    <axis xyz="0 1 0"/>
  </joint>
  <link name="r13_LF_roller_link">
    <visual>
      <geometry>
        <mesh filename="package://robomaster_om_description/meshes/DAE/roller/roller.dae"/>
      </geometry>
    </visual>
    <collision>
      <geometry>
        <mesh filename="package://robomaster_om_description/meshes/STL/roller/roller.stl"/>
      </geometry>
    </collision>
    <inertial>
      <origin xyz="0.0 0.0 0.0"/>
      <mass value="0.009"/>
      <inertia ixx="0.000001257" ixy="0" ixz="0" iyy="0.000000342" iyz="0" izz="0.000001257"/>
    </inertial>
    <surface>
      <friction>
        <ode>
          <mu1>1.2</mu1>
          <mu2>1.2</mu2>
          <kp>1e15</kp>
          <kd>1e13</kd>
        </ode>
      </friction>
      <bounce>
        <restitution_coefficient>0.01</restitution_coefficient>
        <threshold>0</threshold>
      </bounce>
      <contact>
        <ode>
          <max_vel>10</max_vel>
        </ode>
      </contact>
    </surface>
  </link>
  -
  
  <joint name="r14_LF_roller_joint" type="continuous">
    <origin rpy="0.74 -0.48 -0.7854" xyz="-0.058902 -0.0143 0.031483"/>
    <parent link="left_front_wheel_link"/>
    <child link="r14_LF_roller_link"/>
    <axis xyz="0 1 0"/>
  </joint>
  <link name="r14_LF_roller_link">
    <visual>
      <geometry>
        <mesh filename="package://robomaster_om_description/meshes/DAE/roller/roller.dae"/>
      </geometry>
    </visual>
    <collision>
      <geometry>
        <mesh filename="package://robomaster_om_description/meshes/STL/roller/roller.stl"/>
      </geometry>
    </collision>
    <inertial>
      <origin xyz="0.0 0.0 0.0"/>
      <mass value="0.009"/>
      <inertia ixx="0.000001257" ixy="0" ixz="0" iyy="0.000000342" iyz="0" izz="0.000001257"/>
    </inertial>
    <surface>
      <friction>
        <ode>
          <mu1>1.2</mu1>
          <mu2>1.2</mu2>
          <kp>1e15</kp>
          <kd>1e13</kd>
        </ode>
      </friction>
      <bounce>
        <restitution_coefficient>0.01</restitution_coefficient>
        <threshold>0</threshold>
      </bounce>
      <contact>
        <ode>
          <max_vel>10</max_vel>
        </ode>
      </contact>
    </surface>
  </link>
  <joint name="r15_LF_roller_joint" type="continuous">
    <origin rpy="0.51 -0.3194 -0.7854" xyz="-0.04237 -0.0143 0.051628"/>
    <parent link="left_front_wheel_link"/>
    <child link="r15_LF_roller_link"/>
    <axis xyz="0 1 0"/>
  </joint>
  <link name="r15_LF_roller_link">
    <visual>
      <geometry>
        <mesh filename="package://robomaster_om_description/meshes/DAE/roller/roller.dae"/>
      </geometry>
    </visual>
    <collision>
      <geometry>
        <mesh filename="package://robomaster_om_description/meshes/STL/roller/roller.stl"/>
      </geometry>
    </collision>
    <inertial>
      <origin xyz="0.0 0.0 0.0"/>
      <mass value="0.009"/>
      <inertia ixx="0.000001257" ixy="0" ixz="0" iyy="0.000000342" iyz="0" izz="0.000001257"/>
    </inertial>
    <surface>
      <friction>
        <ode>
          <mu1>1.2</mu1>
          <mu2>1.2</mu2>
          <kp>1e15</kp>
          <kd>1e13</kd>
        </ode>
      </friction>
      <bounce>
        <restitution_coefficient>0.01</restitution_coefficient>
        <threshold>0</threshold>
      </bounce>
      <contact>
        <ode>
          <max_vel>10</max_vel>
        </ode>
      </contact>
    </surface>
  </link>
  <joint name="r16_LF_roller_joint" type="continuous">
    <origin rpy="0.2 -0.1117 -0.7854" xyz="-0.019388 -0.0143 0.063912"/>
    <parent link="left_front_wheel_link"/>
    <child link="r16_LF_roller_link"/>
    <axis xyz="0 1 0"/>
  </joint>
  <link name="r16_LF_roller_link">
    <visual>
      <geometry>
        <mesh filename="package://robomaster_om_description/meshes/DAE/roller/roller.dae"/>
      </geometry>
    </visual>
    <collision>
      <geometry>
        <mesh filename="package://robomaster_om_description/meshes/STL/roller/roller.stl"/>
      </geometry>
    </collision>
    <inertial>
      <origin xyz="0.0 0.0 0.0"/>
      <mass value="0.009"/>
      <inertia ixx="0.000001257" ixy="0" ixz="0" iyy="0.000000342" iyz="0" izz="0.000001257"/>
    </inertial>
    <surface>
      <friction>
        <ode>
          <mu1>1.2</mu1>
          <mu2>1.2</mu2>
          <kp>1e15</kp>
          <kd>1e13</kd>
        </ode>
      </friction>
      <bounce>
        <restitution_coefficient>0.01</restitution_coefficient>
        <threshold>0</threshold>
      </bounce>
      <contact>
        <ode>
          <max_vel>10</max_vel>
        </ode>
      </contact>
    </surface>
  </link>
  <joint name="right_rear_wheel_joint" type="continuous">
    <origin xyz="-0.3765 -0.1826 -0.0345"/>
    <parent link="base_link"/>
    <child link="right_rear_wheel_link"/>
    <limit effort="100" velocity="100"/>
    <axis xyz="0 1 0"/>
  </joint>
  <link name="right_rear_wheel_link">
    <visual>
      <geometry>
        <mesh filename="package://robomaster_om_description/meshes/DAE/wheel/wheel_link.dae"/>
      </geometry>
    </visual>
    <collision>
      <geometry>
        <mesh filename="package://robomaster_om_description/meshes/STL/mecanum_wheel/mecanum_wheel.stl"/>
      </geometry>
    </collision>
    <inertial>
      <origin xyz="0.0 -0.011 -0.0"/>
      <mass value="0.25"/>
      <inertia ixx="0.00031" ixy="0" ixz="0" iyy="0.0005" iyz="0" izz="0.00031"/>
    </inertial>
    <surface>
      <friction>
        <ode>
          <mu1>1.2</mu1>
          <mu2>1.2</mu2>
          <kp>1e15</kp>
          <kd>1e13</kd>
        </ode>
      </friction>
      <bounce>
        <restitution_coefficient>0.01</restitution_coefficient>
        <threshold>0</threshold>
      </bounce>
      <contact>
        <ode>
          <max_vel>10</max_vel>
        </ode>
      </contact>
    </surface>
  </link>
  <joint name="r1_RR_roller_joint" type="continuous">
    <origin rpy="-0.0698 -0.00524 -0.7854" xyz="0.006546 -0.0143 0.066466"/>
    <parent link="right_rear_wheel_link"/>
    <child link="r1_RR_roller_link"/>
    <axis xyz="0 1 0"/>
  </joint>
  <link name="r1_RR_roller_link">
    <visual>
      <geometry>
        <mesh filename="package://robomaster_om_description/meshes/DAE/roller/roller.dae"/>
      </geometry>
    </visual>
    <collision>
      <geometry>
        <mesh filename="package://robomaster_om_description/meshes/STL/roller/roller.stl"/>
      </geometry>
    </collision>
    <inertial>
      <origin xyz="0.0 0.0 0.0"/>
      <mass value="0.009"/>
      <inertia ixx="0.000001257" ixy="0" ixz="0" iyy="0.000000342" iyz="0" izz="0.000001257"/>
    </inertial>
    <surface>
      <friction>
        <ode>
          <mu1>1.2</mu1>
          <mu2>1.2</mu2>
          <kp>1e15</kp>
          <kd>1e13</kd>
        </ode>
      </friction>
      <bounce>
        <restitution_coefficient>0.01</restitution_coefficient>
        <threshold>0</threshold>
      </bounce>
      <contact>
        <ode>
          <max_vel>10</max_vel>
        </ode>
      </contact>
    </surface>
  </link>
  <joint name="r2_RR_roller_joint" type="continuous">
    <origin rpy="-1.56 -1.26 0.7854" xyz="0.031483 -0.0143 0.058902"/>
    <parent link="right_rear_wheel_link"/>
    <child link="r2_RR_roller_link"/>
    <axis xyz="0 1 0"/>
  </joint>
  <link name="r2_RR_roller_link">
    <visual>
      <geometry>
        <mesh filename="package://robomaster_om_description/meshes/DAE/roller/roller.dae"/>
      </geometry>
    </visual>
    <collision>
      <geometry>
        <mesh filename="package://robomaster_om_description/meshes/STL/roller/roller.stl"/>
      </geometry>
    </collision>
    <inertial>
      <origin xyz="0.0 0.0 0.0"/>
      <mass value="0.009"/>
      <inertia ixx="0.000001257" ixy="0" ixz="0" iyy="0.000000342" iyz="0" izz="0.000001257"/>
    </inertial>
    <surface>
      <friction>
        <ode>
          <mu1>1.2</mu1>
          <mu2>1.2</mu2>
          <kp>1e15</kp>
          <kd>1e13</kd>
        </ode>
      </friction>
      <bounce>
        <restitution_coefficient>0.01</restitution_coefficient>
        <threshold>0</threshold>
      </bounce>
      <contact>
        <ode>
          <max_vel>10</max_vel>
        </ode>
      </contact>
    </surface>
  </link>
  <joint name="r3_RR_roller_joint" type="continuous">
    <origin rpy="-1.36 -1.04 0.7854" xyz="0.051628 -0.0143 0.04237"/>
    <parent link="right_rear_wheel_link"/>
    <child link="r3_RR_roller_link"/>
    <axis xyz="0 1 0"/>
  </joint>
  <link name="r3_RR_roller_link">
    <visual>
      <geometry>
        <mesh filename="package://robomaster_om_description/meshes/DAE/roller/roller.dae"/>
      </geometry>
    </visual>
    <collision>
      <geometry>
        <mesh filename="package://robomaster_om_description/meshes/STL/roller/roller.stl"/>
      </geometry>
    </collision>
    <inertial>
      <origin xyz="0.0 0.0 0.0"/>
      <mass value="0.009"/>
      <inertia ixx="0.000001257" ixy="0" ixz="0" iyy="0.000000342" iyz="0" izz="0.000001257"/>
    </inertial>
    <surface>
      <friction>
        <ode>
          <mu1>1.2</mu1>
          <mu2>1.2</mu2>
          <kp>1e15</kp>
          <kd>1e13</kd>
        </ode>
      </friction>
      <bounce>
        <restitution_coefficient>0.01</restitution_coefficient>
        <threshold>0</threshold>
      </bounce>
      <contact>
        <ode>
          <max_vel>10</max_vel>
        </ode>
      </contact>
    </surface>
  </link>
  <joint name="r4_RR_roller_joint" type="continuous">
    <origin rpy="-1.2 -0.76 0.7854" xyz="0.063912 -0.0143 0.019388"/>
    <parent link="right_rear_wheel_link"/>
    <child link="r4_RR_roller_link"/>
    <axis xyz="0 1 0"/>
  </joint>
  <link name="r4_RR_roller_link">
    <visual>
      <geometry>
        <mesh filename="package://robomaster_om_description/meshes/DAE/roller/roller.dae"/>
      </geometry>
    </visual>
    <collision>
      <geometry>
        <mesh filename="package://robomaster_om_description/meshes/STL/roller/roller.stl"/>
      </geometry>
    </collision>
    <inertial>
      <origin xyz="0.0 0.0 0.0"/>
      <mass value="0.009"/>
      <inertia ixx="0.000001257" ixy="0" ixz="0" iyy="0.000000342" iyz="0" izz="0.000001257"/>
    </inertial>
    <surface>
      <friction>
        <ode>
          <mu1>1.2</mu1>
          <mu2>1.2</mu2>
          <kp>1e15</kp>
          <kd>1e13</kd>
        </ode>
      </friction>
      <bounce>
        <restitution_coefficient>0.01</restitution_coefficient>
        <threshold>0</threshold>
      </bounce>
      <contact>
        <ode>
          <max_vel>10</max_vel>
        </ode>
      </contact>
    </surface>
  </link>
  <joint name="r5_RR_roller_joint" type="continuous">
    <origin rpy="-1.0 -0.58 0.7854" xyz="0.066466 -0.0143 -0.006546"/>
    <parent link="right_rear_wheel_link"/>
    <child link="r5_RR_roller_link"/>
    <axis xyz="0 1 0"/>
  </joint>
  <link name="r5_RR_roller_link">
    <visual>
      <geometry>
        <mesh filename="package://robomaster_om_description/meshes/DAE/roller/roller.dae"/>
      </geometry>
    </visual>
    <collision>
      <geometry>
        <mesh filename="package://robomaster_om_description/meshes/STL/roller/roller.stl"/>
      </geometry>
    </collision>
    <inertial>
      <origin xyz="0.0 0.0 0.0"/>
      <mass value="0.009"/>
      <inertia ixx="0.000001257" ixy="0" ixz="0" iyy="0.000000342" iyz="0" izz="0.000001257"/>
    </inertial>
    <surface>
      <friction>
        <ode>
          <mu1>1.2</mu1>
          <mu2>1.2</mu2>
          <kp>1e15</kp>
          <kd>1e13</kd>
        </ode>
      </friction>
      <bounce>
        <restitution_coefficient>0.01</restitution_coefficient>
        <threshold>0</threshold>
      </bounce>
      <contact>
        <ode>
          <max_vel>10</max_vel>
        </ode>
      </contact>
    </surface>
  </link>
  <joint name="r6_RR_roller_joint" type="continuous">
    <origin rpy="-0.74 -0.48 0.7854" xyz="0.058902 -0.0143 -0.031483"/>
    <parent link="right_rear_wheel_link"/>
    <child link="r6_RR_roller_link"/>
    <axis xyz="0 1 0"/>
  </joint>
  <link name="r6_RR_roller_link">
    <visual>
      <geometry>
        <mesh filename="package://robomaster_om_description/meshes/DAE/roller/roller.dae"/>
      </geometry>
    </visual>
    <collision>
      <geometry>
        <mesh filename="package://robomaster_om_description/meshes/STL/roller/roller.stl"/>
      </geometry>
    </collision>
    <inertial>
      <origin xyz="0.0 0.0 0.0"/>
      <mass value="0.009"/>
      <inertia ixx="0.000001257" ixy="0" ixz="0" iyy="0.000000342" iyz="0" izz="0.000001257"/>
    </inertial>
    <surface>
      <friction>
        <ode>
          <mu1>1.2</mu1>
          <mu2>1.2</mu2>
          <kp>1e15</kp>
          <kd>1e13</kd>
        </ode>
      </friction>
      <bounce>
        <restitution_coefficient>0.01</restitution_coefficient>
        <threshold>0</threshold>
      </bounce>
      <contact>
        <ode>
          <max_vel>10</max_vel>
        </ode>
      </contact>
    </surface>
  </link>
  <joint name="r7_RR_roller_joint" type="continuous">
    <origin rpy="-0.51 -0.3194 0.7854" xyz="0.04237 -0.0143 -0.051628"/>
    <parent link="right_rear_wheel_link"/>
    <child link="r7_RR_roller_link"/>
    <axis xyz="0 1 0"/>
  </joint>
  <link name="r7_RR_roller_link">
    <visual>
      <geometry>
        <mesh filename="package://robomaster_om_description/meshes/DAE/roller/roller.dae"/>
      </geometry>
    </visual>
    <collision>
      <geometry>
        <mesh filename="package://robomaster_om_description/meshes/STL/roller/roller.stl"/>
      </geometry>
    </collision>
    <inertial>
      <origin xyz="0.0 0.0 0.0"/>
      <mass value="0.009"/>
      <inertia ixx="0.000001257" ixy="0" ixz="0" iyy="0.000000342" iyz="0" izz="0.000001257"/>
    </inertial>
    <surface>
      <friction>
        <ode>
          <mu1>1.2</mu1>
          <mu2>1.2</mu2>
          <kp>1e15</kp>
          <kd>1e13</kd>
        </ode>
      </friction>
      <bounce>
        <restitution_coefficient>0.01</restitution_coefficient>
        <threshold>0</threshold>
      </bounce>
      <contact>
        <ode>
          <max_vel>10</max_vel>
        </ode>
      </contact>
    </surface>
  </link>
  <joint name="r8_RR_roller_joint" type="continuous">
    <origin rpy="-0.2 -0.1117 0.7854" xyz="0.019388 -0.0143 -0.063912"/>
    <parent link="right_rear_wheel_link"/>
    <child link="r8_RR_roller_link"/>
    <axis xyz="0 1 0"/>
  </joint>
  <link name="r8_RR_roller_link">
    <visual>
      <geometry>
        <mesh filename="package://robomaster_om_description/meshes/DAE/roller/roller.dae"/>
      </geometry>
    </visual>
    <collision>
      <geometry>
        <mesh filename="package://robomaster_om_description/meshes/STL/roller/roller.stl"/>
      </geometry>
    </collision>
    <inertial>
      <origin xyz="0.0 0.0 0.0"/>
      <mass value="0.009"/>
      <inertia ixx="0.000001257" ixy="0" ixz="0" iyy="0.000000342" iyz="0" izz="0.000001257"/>
    </inertial>
    <surface>
      <friction>
        <ode>
          <mu1>1.2</mu1>
          <mu2>1.2</mu2>
          <kp>1e15</kp>
          <kd>1e13</kd>
        </ode>
      </friction>
      <bounce>
        <restitution_coefficient>0.01</restitution_coefficient>
        <threshold>0</threshold>
      </bounce>
      <contact>
        <ode>
          <max_vel>10</max_vel>
        </ode>
      </contact>
    </surface>
  </link>
  <joint name="r9_RR_roller_joint" type="continuous">
    <origin rpy="0.0698 -0.00524 0.7854" xyz="-0.006546 -0.0143 -0.066466"/>
    <parent link="right_rear_wheel_link"/>
    <child link="r9_RR_roller_link"/>
    <axis xyz="0 1 0"/>
  </joint>
  <link name="r9_RR_roller_link">
    <visual>
      <geometry>
        <mesh filename="package://robomaster_om_description/meshes/DAE/roller/roller.dae"/>
      </geometry>
    </visual>
    <collision>
      <geometry>
        <mesh filename="package://robomaster_om_description/meshes/STL/roller/roller.stl"/>
      </geometry>
    </collision>
    <inertial>
      <origin xyz="0.0 0.0 0.0"/>
      <mass value="0.009"/>
      <inertia ixx="0.000001257" ixy="0" ixz="0" iyy="0.000000342" iyz="0" izz="0.000001257"/>
    </inertial>
    <surface>
      <friction>
        <ode>
          <mu1>1.2</mu1>
          <mu2>1.2</mu2>
          <kp>1e15</kp>
          <kd>1e13</kd>
        </ode>
      </friction>
      <bounce>
        <restitution_coefficient>0.01</restitution_coefficient>
        <threshold>0</threshold>
      </bounce>
      <contact>
        <ode>
          <max_vel>10</max_vel>
        </ode>
      </contact>
    </surface>
  </link>
  <joint name="r10_RR_roller_joint" type="continuous">
    <origin rpy="1.56 -1.26 -0.7854" xyz="-0.031483 -0.0143 -0.058902"/>
    <parent link="right_rear_wheel_link"/>
    <child link="r10_RR_roller_link"/>
    <axis xyz="0 1 0"/>
  </joint>
  <link name="r10_RR_roller_link">
    <visual>
      <geometry>
        <mesh filename="package://robomaster_om_description/meshes/DAE/roller/roller.dae"/>
      </geometry>
    </visual>
    <collision>
      <geometry>
        <mesh filename="package://robomaster_om_description/meshes/STL/roller/roller.stl"/>
      </geometry>
    </collision>
    <inertial>
      <origin xyz="0.0 0.0 0.0"/>
      <mass value="0.009"/>
      <inertia ixx="0.000001257" ixy="0" ixz="0" iyy="0.000000342" iyz="0" izz="0.000001257"/>
    </inertial>
    <surface>
      <friction>
        <ode>
          <mu1>1.2</mu1>
          <mu2>1.2</mu2>
          <kp>1e15</kp>
          <kd>1e13</kd>
        </ode>
      </friction>
      <bounce>
        <restitution_coefficient>0.01</restitution_coefficient>
        <threshold>0</threshold>
      </bounce>
      <contact>
        <ode>
          <max_vel>10</max_vel>
        </ode>
      </contact>
    </surface>
  </link>
  <joint name="r11_RR_roller_joint" type="continuous">
    <origin rpy="1.36 -1.04 -0.7854" xyz="-0.051628 -0.0143 -0.04237"/>
    <parent link="right_rear_wheel_link"/>
    <child link="r11_RR_roller_link"/>
    <axis xyz="0 1 0"/>
  </joint>
  <link name="r11_RR_roller_link">
    <visual>
      <geometry>
        <mesh filename="package://robomaster_om_description/meshes/DAE/roller/roller.dae"/>
      </geometry>
    </visual>
    <collision>
      <geometry>
        <mesh filename="package://robomaster_om_description/meshes/STL/roller/roller.stl"/>
      </geometry>
    </collision>
    <inertial>
      <origin xyz="0.0 0.0 0.0"/>
      <mass value="0.009"/>
      <inertia ixx="0.000001257" ixy="0" ixz="0" iyy="0.000000342" iyz="0" izz="0.000001257"/>
    </inertial>
    <surface>
      <friction>
        <ode>
          <mu1>1.2</mu1>
          <mu2>1.2</mu2>
          <kp>1e15</kp>
          <kd>1e13</kd>
        </ode>
      </friction>
      <bounce>
        <restitution_coefficient>0.01</restitution_coefficient>
        <threshold>0</threshold>
      </bounce>
      <contact>
        <ode>
          <max_vel>10</max_vel>
        </ode>
      </contact>
    </surface>
  </link>
  <joint name="r12_RR_roller_joint" type="continuous">
    <origin rpy="1.2 -0.76 -0.7854" xyz="-0.063912 -0.0143 -0.019388"/>
    <parent link="right_rear_wheel_link"/>
    <child link="r12_RR_roller_link"/>
    <axis xyz="0 1 0"/>
  </joint>
  <link name="r12_RR_roller_link">
    <visual>
      <geometry>
        <mesh filename="package://robomaster_om_description/meshes/DAE/roller/roller.dae"/>
      </geometry>
    </visual>
    <collision>
      <geometry>
        <mesh filename="package://robomaster_om_description/meshes/STL/roller/roller.stl"/>
      </geometry>
    </collision>
    <inertial>
      <origin xyz="0.0 0.0 0.0"/>
      <mass value="0.009"/>
      <inertia ixx="0.000001257" ixy="0" ixz="0" iyy="0.000000342" iyz="0" izz="0.000001257"/>
    </inertial>
    <surface>
      <friction>
        <ode>
          <mu1>1.2</mu1>
          <mu2>1.2</mu2>
          <kp>1e15</kp>
          <kd>1e13</kd>
        </ode>
      </friction>
      <bounce>
        <restitution_coefficient>0.01</restitution_coefficient>
        <threshold>0</threshold>
      </bounce>
      <contact>
        <ode>
          <max_vel>10</max_vel>
        </ode>
      </contact>
    </surface>
  </link>
  <joint name="r13_RR_roller_joint" type="continuous">
    <origin rpy="1.0 -0.58 -0.7854" xyz="-0.066466 -0.0143 0.006546"/>
    <parent link="right_rear_wheel_link"/>
    <child link="r13_RR_roller_link"/>
    <axis xyz="0 1 0"/>
  </joint>
  <link name="r13_RR_roller_link">
    <visual>
      <geometry>
        <mesh filename="package://robomaster_om_description/meshes/DAE/roller/roller.dae"/>
      </geometry>
    </visual>
    <collision>
      <geometry>
        <mesh filename="package://robomaster_om_description/meshes/STL/roller/roller.stl"/>
      </geometry>
    </collision>
    <inertial>
      <origin xyz="0.0 0.0 0.0"/>
      <mass value="0.009"/>
      <inertia ixx="0.000001257" ixy="0" ixz="0" iyy="0.000000342" iyz="0" izz="0.000001257"/>
    </inertial>
    <surface>
      <friction>
        <ode>
          <mu1>1.2</mu1>
          <mu2>1.2</mu2>
          <kp>1e15</kp>
          <kd>1e13</kd>
        </ode>
      </friction>
      <bounce>
        <restitution_coefficient>0.01</restitution_coefficient>
        <threshold>0</threshold>
      </bounce>
      <contact>
        <ode>
          <max_vel>10</max_vel>
        </ode>
      </contact>
    </surface>
  </link>
  -
  
  <joint name="r14_RR_roller_joint" type="continuous">
    <origin rpy="0.74 -0.48 -0.7854" xyz="-0.058902 -0.0143 0.031483"/>
    <parent link="right_rear_wheel_link"/>
    <child link="r14_RR_roller_link"/>
    <axis xyz="0 1 0"/>
  </joint>
  <link name="r14_RR_roller_link">
    <visual>
      <geometry>
        <mesh filename="package://robomaster_om_description/meshes/DAE/roller/roller.dae"/>
      </geometry>
    </visual>
    <collision>
      <geometry>
        <mesh filename="package://robomaster_om_description/meshes/STL/roller/roller.stl"/>
      </geometry>
    </collision>
    <inertial>
      <origin xyz="0.0 0.0 0.0"/>
      <mass value="0.009"/>
      <inertia ixx="0.000001257" ixy="0" ixz="0" iyy="0.000000342" iyz="0" izz="0.000001257"/>
    </inertial>
    <surface>
      <friction>
        <ode>
          <mu1>1.2</mu1>
          <mu2>1.2</mu2>
          <kp>1e15</kp>
          <kd>1e13</kd>
        </ode>
      </friction>
      <bounce>
        <restitution_coefficient>0.01</restitution_coefficient>
        <threshold>0</threshold>
      </bounce>
      <contact>
        <ode>
          <max_vel>10</max_vel>
        </ode>
      </contact>
    </surface>
  </link>
  <joint name="r15_RR_roller_joint" type="continuous">
    <origin rpy="0.51 -0.3194 -0.7854" xyz="-0.04237 -0.0143 0.051628"/>
    <parent link="right_rear_wheel_link"/>
    <child link="r15_RR_roller_link"/>
    <axis xyz="0 1 0"/>
  </joint>
  <link name="r15_RR_roller_link">
    <visual>
      <geometry>
        <mesh filename="package://robomaster_om_description/meshes/DAE/roller/roller.dae"/>
      </geometry>
    </visual>
    <collision>
      <geometry>
        <mesh filename="package://robomaster_om_description/meshes/STL/roller/roller.stl"/>
      </geometry>
    </collision>
    <inertial>
      <origin xyz="0.0 0.0 0.0"/>
      <mass value="0.009"/>
      <inertia ixx="0.000001257" ixy="0" ixz="0" iyy="0.000000342" iyz="0" izz="0.000001257"/>
    </inertial>
    <surface>
      <friction>
        <ode>
          <mu1>1.2</mu1>
          <mu2>1.2</mu2>
          <kp>1e15</kp>
          <kd>1e13</kd>
        </ode>
      </friction>
      <bounce>
        <restitution_coefficient>0.01</restitution_coefficient>
        <threshold>0</threshold>
      </bounce>
      <contact>
        <ode>
          <max_vel>10</max_vel>
        </ode>
      </contact>
    </surface>
  </link>
  <joint name="r16_RR_roller_joint" type="continuous">
    <origin rpy="0.2 -0.1117 -0.7854" xyz="-0.019388 -0.0143 0.063912"/>
    <parent link="right_rear_wheel_link"/>
    <child link="r16_RR_roller_link"/>
    <axis xyz="0 1 0"/>
  </joint>
  <link name="r16_RR_roller_link">
    <visual>
      <geometry>
        <mesh filename="package://robomaster_om_description/meshes/DAE/roller/roller.dae"/>
      </geometry>
    </visual>
    <collision>
      <geometry>
        <mesh filename="package://robomaster_om_description/meshes/STL/roller/roller.stl"/>
      </geometry>
    </collision>
    <inertial>
      <origin xyz="0.0 0.0 0.0"/>
      <mass value="0.009"/>
      <inertia ixx="0.000001257" ixy="0" ixz="0" iyy="0.000000342" iyz="0" izz="0.000001257"/>
    </inertial>
    <surface>
      <friction>
        <ode>
          <mu1>1.2</mu1>
          <mu2>1.2</mu2>
          <kp>1e15</kp>
          <kd>1e13</kd>
        </ode>
      </friction>
      <bounce>
        <restitution_coefficient>0.01</restitution_coefficient>
        <threshold>0</threshold>
      </bounce>
      <contact>
        <ode>
          <max_vel>10</max_vel>
        </ode>
      </contact>
    </surface>
  </link>
  <joint name="left_rear_wheel_joint" type="continuous">
    <origin rpy="0 0 3.14159274" xyz="-0.3765 0.1826 -0.0345"/>
    <parent link="base_link"/>
    <child link="left_rear_wheel_link"/>
    <limit effort="100" velocity="100"/>
    <axis xyz="0 -1 0"/>
  </joint>
  <link name="left_rear_wheel_link">
    <visual>
      <geometry>
        <mesh filename="package://robomaster_om_description/meshes/DAE/wheel/wheel_link.dae"/>
      </geometry>
    </visual>
    <collision>
      <geometry>
        <mesh filename="package://robomaster_om_description/meshes/STL/mecanum_wheel/mecanum_wheel.stl"/>
      </geometry>
    </collision>
    <inertial>
      <origin xyz="0.0 -0.011 -0.0"/>
      <mass value="0.25"/>
      <inertia ixx="0.00031" ixy="0" ixz="0" iyy="0.0005" iyz="0" izz="0.00031"/>
    </inertial>
    <surface>
      <friction>
        <ode>
          <mu1>1.2</mu1>
          <mu2>1.2</mu2>
          <kp>1e15</kp>
          <kd>1e13</kd>
        </ode>
      </friction>
      <bounce>
        <restitution_coefficient>0.01</restitution_coefficient>
        <threshold>0</threshold>
      </bounce>
      <contact>
        <ode>
          <max_vel>10</max_vel>
        </ode>
      </contact>
    </surface>
  </link>
  <joint name="r1_LR_roller_joint" type="continuous">
    <origin rpy="-0.0698 -0.00524 0.7854" xyz="-0.006546 -0.0143 0.066466"/>
    <parent link="left_rear_wheel_link"/>
    <child link="r1_LR_roller_link"/>
    <axis xyz="0 1 0"/>
  </joint>
  <link name="r1_LR_roller_link">
    <visual>
      <geometry>
        <mesh filename="package://robomaster_om_description/meshes/DAE/roller/roller.dae"/>
      </geometry>
    </visual>
    <collision>
      <geometry>
        <mesh filename="package://robomaster_om_description/meshes/STL/roller/roller.stl"/>
      </geometry>
    </collision>
    <inertial>
      <origin xyz="0.0 0.0 0.0"/>
      <mass value="0.009"/>
      <inertia ixx="0.000001257" ixy="0" ixz="0" iyy="0.000000342" iyz="0" izz="0.000001257"/>
    </inertial>
    <surface>
      <friction>
        <ode>
          <mu1>1.2</mu1>
          <mu2>1.2</mu2>
          <kp>1e15</kp>
          <kd>1e13</kd>
        </ode>
      </friction>
      <bounce>
        <restitution_coefficient>0.01</restitution_coefficient>
        <threshold>0</threshold>
      </bounce>
      <contact>
        <ode>
          <max_vel>10</max_vel>
        </ode>
      </contact>
    </surface>
  </link>
  <joint name="r2_LR_roller_joint" type="continuous">
    <origin rpy="-0.342 -0.1117 0.7854" xyz="-0.031483 -0.0143 0.058902"/>
    <parent link="left_rear_wheel_link"/>
    <child link="r2_LR_roller_link"/>
    <axis xyz="0 1 0"/>
  </joint>
  <link name="r2_LR_roller_link">
    <visual>
      <geometry>
        <mesh filename="package://robomaster_om_description/meshes/DAE/roller/roller.dae"/>
      </geometry>
    </visual>
    <collision>
      <geometry>
        <mesh filename="package://robomaster_om_description/meshes/STL/roller/roller.stl"/>
      </geometry>
    </collision>
    <inertial>
      <origin xyz="0.0 0.0 0.0"/>
      <mass value="0.009"/>
      <inertia ixx="0.000001257" ixy="0" ixz="0" iyy="0.000000342" iyz="0" izz="0.000001257"/>
    </inertial>
    <surface>
      <friction>
        <ode>
          <mu1>1.2</mu1>
          <mu2>1.2</mu2>
          <kp>1e15</kp>
          <kd>1e13</kd>
        </ode>
      </friction>
      <bounce>
        <restitution_coefficient>0.01</restitution_coefficient>
        <threshold>0</threshold>
      </bounce>
      <contact>
        <ode>
          <max_vel>10</max_vel>
        </ode>
      </contact>
    </surface>
  </link>
  <joint name="r3_LR_roller_joint" type="continuous">
    <origin rpy="-0.5777 -0.3194 0.7854" xyz="-0.051628 -0.0143 0.04237"/>
    <parent link="left_rear_wheel_link"/>
    <child link="r3_LR_roller_link"/>
    <axis xyz="0 1 0"/>
  </joint>
  <link name="r3_LR_roller_link">
    <visual>
      <geometry>
        <mesh filename="package://robomaster_om_description/meshes/DAE/roller/roller.dae"/>
      </geometry>
    </visual>
    <collision>
      <geometry>
        <mesh filename="package://robomaster_om_description/meshes/STL/roller/roller.stl"/>
      </geometry>
    </collision>
    <inertial>
      <origin xyz="0.0 0.0 0.0"/>
      <mass value="0.009"/>
      <inertia ixx="0.000001257" ixy="0" ixz="0" iyy="0.000000342" iyz="0" izz="0.000001257"/>
    </inertial>
    <surface>
      <friction>
        <ode>
          <mu1>1.2</mu1>
          <mu2>1.2</mu2>
          <kp>1e15</kp>
          <kd>1e13</kd>
        </ode>
      </friction>
      <bounce>
        <restitution_coefficient>0.01</restitution_coefficient>
        <threshold>0</threshold>
      </bounce>
      <contact>
        <ode>
          <max_vel>10</max_vel>
        </ode>
      </contact>
    </surface>
  </link>
  <joint name="r4_LR_roller_joint" type="continuous">
    <origin rpy="-0.82 -0.52 0.7854" xyz="-0.063912 -0.0143 0.019388"/>
    <parent link="left_rear_wheel_link"/>
    <child link="r4_LR_roller_link"/>
    <axis xyz="0 1 0"/>
  </joint>
  <link name="r4_LR_roller_link">
    <visual>
      <geometry>
        <mesh filename="package://robomaster_om_description/meshes/DAE/roller/roller.dae"/>
      </geometry>
    </visual>
    <collision>
      <geometry>
        <mesh filename="package://robomaster_om_description/meshes/STL/roller/roller.stl"/>
      </geometry>
    </collision>
    <inertial>
      <origin xyz="0.0 0.0 0.0"/>
      <mass value="0.009"/>
      <inertia ixx="0.000001257" ixy="0" ixz="0" iyy="0.000000342" iyz="0" izz="0.000001257"/>
    </inertial>
    <surface>
      <friction>
        <ode>
          <mu1>1.2</mu1>
          <mu2>1.2</mu2>
          <kp>1e15</kp>
          <kd>1e13</kd>
        </ode>
      </friction>
      <bounce>
        <restitution_coefficient>0.01</restitution_coefficient>
        <threshold>0</threshold>
      </bounce>
      <contact>
        <ode>
          <max_vel>10</max_vel>
        </ode>
      </contact>
    </surface>
  </link>
  <joint name="r5_LR_roller_joint" type="continuous">
    <origin rpy="-1.08 -0.62 0.7854" xyz="-0.066466 -0.0143 -0.006546"/>
    <parent link="left_rear_wheel_link"/>
    <child link="r5_LR_roller_link"/>
    <axis xyz="0 1 0"/>
  </joint>
  <link name="r5_LR_roller_link">
    <visual>
      <geometry>
        <mesh filename="package://robomaster_om_description/meshes/DAE/roller/roller.dae"/>
      </geometry>
    </visual>
    <collision>
      <geometry>
        <mesh filename="package://robomaster_om_description/meshes/STL/roller/roller.stl"/>
      </geometry>
    </collision>
    <inertial>
      <origin xyz="0.0 0.0 0.0"/>
      <mass value="0.009"/>
      <inertia ixx="0.000001257" ixy="0" ixz="0" iyy="0.000000342" iyz="0" izz="0.000001257"/>
    </inertial>
    <surface>
      <friction>
        <ode>
          <mu1>1.2</mu1>
          <mu2>1.2</mu2>
          <kp>1e15</kp>
          <kd>1e13</kd>
        </ode>
      </friction>
      <bounce>
        <restitution_coefficient>0.01</restitution_coefficient>
        <threshold>0</threshold>
      </bounce>
      <contact>
        <ode>
          <max_vel>10</max_vel>
        </ode>
      </contact>
    </surface>
  </link>
  <joint name="r6_LR_roller_joint" type="continuous">
    <origin rpy="-1.28 -0.82 0.7854" xyz="-0.058902 -0.0143 -0.031483"/>
    <parent link="left_rear_wheel_link"/>
    <child link="r6_LR_roller_link"/>
    <axis xyz="0 1 0"/>
  </joint>
  <link name="r6_LR_roller_link">
    <visual>
      <geometry>
        <mesh filename="package://robomaster_om_description/meshes/DAE/roller/roller.dae"/>
      </geometry>
    </visual>
    <collision>
      <geometry>
        <mesh filename="package://robomaster_om_description/meshes/STL/roller/roller.stl"/>
      </geometry>
    </collision>
    <inertial>
      <origin xyz="0.0 0.0 0.0"/>
      <mass value="0.009"/>
      <inertia ixx="0.000001257" ixy="0" ixz="0" iyy="0.000000342" iyz="0" izz="0.000001257"/>
    </inertial>
    <surface>
      <friction>
        <ode>
          <mu1>1.2</mu1>
          <mu2>1.2</mu2>
          <kp>1e15</kp>
          <kd>1e13</kd>
        </ode>
      </friction>
      <bounce>
        <restitution_coefficient>0.01</restitution_coefficient>
        <threshold>0</threshold>
      </bounce>
      <contact>
        <ode>
          <max_vel>10</max_vel>
        </ode>
      </contact>
    </surface>
  </link>
  <joint name="r7_LR_roller_joint" type="continuous">
    <origin rpy="-1.44 -1.1 0.7854" xyz="-0.04237 -0.0143 -0.051628"/>
    <parent link="left_rear_wheel_link"/>
    <child link="r7_LR_roller_link"/>
    <axis xyz="0 1 0"/>
  </joint>
  <link name="r7_LR_roller_link">
    <visual>
      <geometry>
        <mesh filename="package://robomaster_om_description/meshes/DAE/roller/roller.dae"/>
      </geometry>
    </visual>
    <collision>
      <geometry>
        <mesh filename="package://robomaster_om_description/meshes/STL/roller/roller.stl"/>
      </geometry>
    </collision>
    <inertial>
      <origin xyz="0.0 0.0 0.0"/>
      <mass value="0.009"/>
      <inertia ixx="0.000001257" ixy="0" ixz="0" iyy="0.000000342" iyz="0" izz="0.000001257"/>
    </inertial>
    <surface>
      <friction>
        <ode>
          <mu1>1.2</mu1>
          <mu2>1.2</mu2>
          <kp>1e15</kp>
          <kd>1e13</kd>
        </ode>
      </friction>
      <bounce>
        <restitution_coefficient>0.01</restitution_coefficient>
        <threshold>0</threshold>
      </bounce>
      <contact>
        <ode>
          <max_vel>10</max_vel>
        </ode>
      </contact>
    </surface>
  </link>
  <joint name="r8_LR_roller_joint" type="continuous">
    <origin rpy="-1.56 -1.36 0.7854" xyz="-0.019388 -0.0143 -0.063912"/>
    <parent link="left_rear_wheel_link"/>
    <child link="r8_LR_roller_link"/>
    <axis xyz="0 1 0"/>
  </joint>
  <link name="r8_LR_roller_link">
    <visual>
      <geometry>
        <mesh filename="package://robomaster_om_description/meshes/DAE/roller/roller.dae"/>
      </geometry>
    </visual>
    <collision>
      <geometry>
        <mesh filename="package://robomaster_om_description/meshes/STL/roller/roller.stl"/>
      </geometry>
    </collision>
    <inertial>
      <origin xyz="0.0 0.0 0.0"/>
      <mass value="0.009"/>
      <inertia ixx="0.000001257" ixy="0" ixz="0" iyy="0.000000342" iyz="0" izz="0.000001257"/>
    </inertial>
    <surface>
      <friction>
        <ode>
          <mu1>1.2</mu1>
          <mu2>1.2</mu2>
          <kp>1e15</kp>
          <kd>1e13</kd>
        </ode>
      </friction>
      <bounce>
        <restitution_coefficient>0.01</restitution_coefficient>
        <threshold>0</threshold>
      </bounce>
      <contact>
        <ode>
          <max_vel>10</max_vel>
        </ode>
      </contact>
    </surface>
  </link>
  <joint name="r9_LR_roller_joint" type="continuous">
    <origin rpy="0.0698 -0.00524 -0.7854" xyz="0.006546 -0.0143 -0.066466"/>
    <parent link="left_rear_wheel_link"/>
    <child link="r9_LR_roller_link"/>
    <axis xyz="0 1 0"/>
  </joint>
  <link name="r9_LR_roller_link">
    <visual>
      <geometry>
        <mesh filename="package://robomaster_om_description/meshes/DAE/roller/roller.dae"/>
      </geometry>
    </visual>
    <collision>
      <geometry>
        <mesh filename="package://robomaster_om_description/meshes/STL/roller/roller.stl"/>
      </geometry>
    </collision>
    <inertial>
      <origin xyz="0.0 0.0 0.0"/>
      <mass value="0.009"/>
      <inertia ixx="0.000001257" ixy="0" ixz="0" iyy="0.000000342" iyz="0" izz="0.000001257"/>
    </inertial>
    <surface>
      <friction>
        <ode>
          <mu1>1.2</mu1>
          <mu2>1.2</mu2>
          <kp>1e15</kp>
          <kd>1e13</kd>
        </ode>
      </friction>
      <bounce>
        <restitution_coefficient>0.01</restitution_coefficient>
        <threshold>0</threshold>
      </bounce>
      <contact>
        <ode>
          <max_vel>10</max_vel>
        </ode>
      </contact>
    </surface>
  </link>
  <joint name="r10_LR_roller_joint" type="continuous">
    <origin rpy="0.342 -0.1117 -0.7854" xyz="0.031483 -0.0143 -0.058902"/>
    <parent link="left_rear_wheel_link"/>
    <child link="r10_LR_roller_link"/>
    <axis xyz="0 1 0"/>
  </joint>
  <link name="r10_LR_roller_link">
    <visual>
      <geometry>
        <mesh filename="package://robomaster_om_description/meshes/DAE/roller/roller.dae"/>
      </geometry>
    </visual>
    <collision>
      <geometry>
        <mesh filename="package://robomaster_om_description/meshes/STL/roller/roller.stl"/>
      </geometry>
    </collision>
    <inertial>
      <origin xyz="0.0 0.0 0.0"/>
      <mass value="0.009"/>
      <inertia ixx="0.000001257" ixy="0" ixz="0" iyy="0.000000342" iyz="0" izz="0.000001257"/>
    </inertial>
    <surface>
      <friction>
        <ode>
          <mu1>1.2</mu1>
          <mu2>1.2</mu2>
          <kp>1e15</kp>
          <kd>1e13</kd>
        </ode>
      </friction>
      <bounce>
        <restitution_coefficient>0.01</restitution_coefficient>
        <threshold>0</threshold>
      </bounce>
      <contact>
        <ode>
          <max_vel>10</max_vel>
        </ode>
      </contact>
    </surface>
  </link>
  <joint name="r11_LR_roller_joint" type="continuous">
    <origin rpy="0.5777 -0.3194 -0.7854" xyz="0.051628 -0.0143 -0.04237"/>
    <parent link="left_rear_wheel_link"/>
    <child link="r11_LR_roller_link"/>
    <axis xyz="0 1 0"/>
  </joint>
  <link name="r11_LR_roller_link">
    <visual>
      <geometry>
        <mesh filename="package://robomaster_om_description/meshes/DAE/roller/roller.dae"/>
      </geometry>
    </visual>
    <collision>
      <geometry>
        <mesh filename="package://robomaster_om_description/meshes/STL/roller/roller.stl"/>
      </geometry>
    </collision>
    <inertial>
      <origin xyz="0.0 0.0 0.0"/>
      <mass value="0.009"/>
      <inertia ixx="0.000001257" ixy="0" ixz="0" iyy="0.000000342" iyz="0" izz="0.000001257"/>
    </inertial>
    <surface>
      <friction>
        <ode>
          <mu1>1.2</mu1>
          <mu2>1.2</mu2>
          <kp>1e15</kp>
          <kd>1e13</kd>
        </ode>
      </friction>
      <bounce>
        <restitution_coefficient>0.01</restitution_coefficient>
        <threshold>0</threshold>
      </bounce>
      <contact>
        <ode>
          <max_vel>10</max_vel>
        </ode>
      </contact>
    </surface>
  </link>
  <joint name="r12_LR_roller_joint" type="continuous">
    <origin rpy="0.82 -0.52 -0.7854" xyz="0.063912 -0.0143 -0.019388"/>
    <parent link="left_rear_wheel_link"/>
    <child link="r12_LR_roller_link"/>
    <axis xyz="0 1 0"/>
  </joint>
  <link name="r12_LR_roller_link">
    <visual>
      <geometry>
        <mesh filename="package://robomaster_om_description/meshes/DAE/roller/roller.dae"/>
      </geometry>
    </visual>
    <collision>
      <geometry>
        <mesh filename="package://robomaster_om_description/meshes/STL/roller/roller.stl"/>
      </geometry>
    </collision>
    <inertial>
      <origin xyz="0.0 0.0 0.0"/>
      <mass value="0.009"/>
      <inertia ixx="0.000001257" ixy="0" ixz="0" iyy="0.000000342" iyz="0" izz="0.000001257"/>
    </inertial>
    <surface>
      <friction>
        <ode>
          <mu1>1.2</mu1>
          <mu2>1.2</mu2>
          <kp>1e15</kp>
          <kd>1e13</kd>
        </ode>
      </friction>
      <bounce>
        <restitution_coefficient>0.01</restitution_coefficient>
        <threshold>0</threshold>
      </bounce>
      <contact>
        <ode>
          <max_vel>10</max_vel>
        </ode>
      </contact>
    </surface>
  </link>
  <joint name="r13_LR_roller_joint" type="continuous">
    <origin rpy="1.08 -0.62 -0.7854" xyz="0.066466 -0.0143 0.006546"/>
    <parent link="left_rear_wheel_link"/>
    <child link="r13_LR_roller_link"/>
    <axis xyz="0 1 0"/>
  </joint>
  <link name="r13_LR_roller_link">
    <visual>
      <geometry>
        <mesh filename="package://robomaster_om_description/meshes/DAE/roller/roller.dae"/>
      </geometry>
    </visual>
    <collision>
      <geometry>
        <mesh filename="package://robomaster_om_description/meshes/STL/roller/roller.stl"/>
      </geometry>
    </collision>
    <inertial>
      <origin xyz="0.0 0.0 0.0"/>
      <mass value="0.009"/>
      <inertia ixx="0.000001257" ixy="0" ixz="0" iyy="0.000000342" iyz="0" izz="0.000001257"/>
    </inertial>
    <surface>
      <friction>
        <ode>
          <mu1>1.2</mu1>
          <mu2>1.2</mu2>
          <kp>1e15</kp>
          <kd>1e13</kd>
        </ode>
      </friction>
      <bounce>
        <restitution_coefficient>0.01</restitution_coefficient>
        <threshold>0</threshold>
      </bounce>
      <contact>
        <ode>
          <max_vel>10</max_vel>
        </ode>
      </contact>
    </surface>
  </link>
  <joint name="r14_LR_roller_joint" type="continuous">
    <origin rpy="1.28 -0.82 -0.7854" xyz="0.058902 -0.0143 0.031483"/>
    <parent link="left_rear_wheel_link"/>
    <child link="r14_LR_roller_link"/>
    <axis xyz="0 1 0"/>
  </joint>
  <link name="r14_LR_roller_link">
    <visual>
      <geometry>
        <mesh filename="package://robomaster_om_description/meshes/DAE/roller/roller.dae"/>
      </geometry>
    </visual>
    <collision>
      <geometry>
        <mesh filename="package://robomaster_om_description/meshes/STL/roller/roller.stl"/>
      </geometry>
    </collision>
    <inertial>
      <origin xyz="0.0 0.0 0.0"/>
      <mass value="0.009"/>
      <inertia ixx="0.000001257" ixy="0" ixz="0" iyy="0.000000342" iyz="0" izz="0.000001257"/>
    </inertial>
    <surface>
      <friction>
        <ode>
          <mu1>1.2</mu1>
          <mu2>1.2</mu2>
          <kp>1e15</kp>
          <kd>1e13</kd>
        </ode>
      </friction>
      <bounce>
        <restitution_coefficient>0.01</restitution_coefficient>
        <threshold>0</threshold>
      </bounce>
      <contact>
        <ode>
          <max_vel>10</max_vel>
        </ode>
      </contact>
    </surface>
  </link>
  <joint name="r15_LR_roller_joint" type="continuous">
    <origin rpy="1.44 -1.1 -0.7854" xyz="0.04237 -0.0143 0.051628"/>
    <parent link="left_rear_wheel_link"/>
    <child link="r15_LR_roller_link"/>
    <axis xyz="0 1 0"/>
  </joint>
  <link name="r15_LR_roller_link">
    <visual>
      <geometry>
        <mesh filename="package://robomaster_om_description/meshes/DAE/roller/roller.dae"/>
      </geometry>
    </visual>
    <collision>
      <geometry>
        <mesh filename="package://robomaster_om_description/meshes/STL/roller/roller.stl"/>
      </geometry>
    </collision>
    <inertial>
      <origin xyz="0.0 0.0 0.0"/>
      <mass value="0.009"/>
      <inertia ixx="0.000001257" ixy="0" ixz="0" iyy="0.000000342" iyz="0" izz="0.000001257"/>
    </inertial>
    <surface>
      <friction>
        <ode>
          <mu1>1.2</mu1>
          <mu2>1.2</mu2>
          <kp>1e15</kp>
          <kd>1e13</kd>
        </ode>
      </friction>
      <bounce>
        <restitution_coefficient>0.01</restitution_coefficient>
        <threshold>0</threshold>
      </bounce>
      <contact>
        <ode>
          <max_vel>10</max_vel>
        </ode>
      </contact>
    </surface>
  </link>
  <joint name="r16_LR_roller_joint" type="continuous">
    <origin rpy="1.56 -1.36 -0.7854" xyz="0.019388 -0.0143 0.063912"/>
    <parent link="left_rear_wheel_link"/>
    <child link="r16_LR_roller_link"/>
    <axis xyz="0 1 0"/>
  </joint>
  <link name="r16_LR_roller_link">
    <visual>
      <geometry>
        <mesh filename="package://robomaster_om_description/meshes/DAE/roller/roller.dae"/>
      </geometry>
    </visual>
    <collision>
      <geometry>
        <mesh filename="package://robomaster_om_description/meshes/STL/roller/roller.stl"/>
      </geometry>
    </collision>
    <inertial>
      <origin xyz="0.0 0.0 0.0"/>
      <mass value="0.009"/>
      <inertia ixx="0.000001257" ixy="0" ixz="0" iyy="0.000000342" iyz="0" izz="0.000001257"/>
    </inertial>
    <surface>
      <friction>
        <ode>
          <mu1>1.2</mu1>
          <mu2>1.2</mu2>
          <kp>1e15</kp>
          <kd>1e13</kd>
        </ode>
      </friction>
      <bounce>
        <restitution_coefficient>0.01</restitution_coefficient>
        <threshold>0</threshold>
      </bounce>
      <contact>
        <ode>
          <max_vel>10</max_vel>
        </ode>
      </contact>
    </surface>
  </link>
  <joint name="base_to_manipulator" type="fixed">
    <parent link="base_link"/>
    <child link="link1"/>
    <origin rpy="0 0 0" xyz="0 0 0"/>
  </joint>
  <!-- LiDAR -->
  <joint name="laser_joint" type="fixed">
    <parent link="base_link"/>
    <child link="laser_frame"/>
    <origin rpy="0 0 0" xyz="-0.175 0 0.075"/>
  </joint>
  <link name="laser_frame">
    <visual>
      <geometry>
        <cylinder length="0.03" radius="0.03"/>
      </geometry>
      <material name="red"/>
    </visual>
    <collision>
      <geometry>
        <cylinder length="0.03" radius="0.03"/>
      </geometry>
    </collision>
  </link>
  <transmission name="right_front_wheel_trans">
    <type>transmission_interface/SimpleTransmission</type>
    <joint name="right_front_wheel_joint">
      <hardwareInterface>hardware_interface/VelocityJointInterface</hardwareInterface>
    </joint>
    <actuator name="right_front_wheel_motor">
      <hardwareInterface>hardware_interface/VelocityJointInterface</hardwareInterface>
      <mechanicalReduction>30</mechanicalReduction>
    </actuator>
  </transmission>
  <transmission name="left_front_wheel_trans">
    <type>transmission_interface/SimpleTransmission</type>
    <joint name="left_front_wheel_joint">
      <hardwareInterface>hardware_interface/VelocityJointInterface</hardwareInterface>
    </joint>
    <actuator name="left_front_wheel_motor">
      <hardwareInterface>hardware_interface/VelocityJointInterface</hardwareInterface>
      <mechanicalReduction>30</mechanicalReduction>
    </actuator>
  </transmission>
  <transmission name="right_rear_wheel_trans">
    <type>transmission_interface/SimpleTransmission</type>
    <joint name="right_rear_wheel_joint">
      <hardwareInterface>hardware_interface/VelocityJointInterface</hardwareInterface>
    </joint>
    <actuator name="right_rear_wheel_motor">
      <hardwareInterface>hardware_interface/VelocityJointInterface</hardwareInterface>
      <mechanicalReduction>30</mechanicalReduction>
    </actuator>
  </transmission>
  <transmission name="left_rear_wheel_trans">
    <type>transmission_interface/SimpleTransmission</type>
    <joint name="left_rear_wheel_joint">
      <hardwareInterface>hardware_interface/VelocityJointInterface</hardwareInterface>
    </joint>
    <actuator name="left_rear_wheel_motor">
      <hardwareInterface>hardware_interface/VelocityJointInterface</hardwareInterface>
      <mechanicalReduction>30</mechanicalReduction>
    </actuator>
  </transmission>
  <!-- =============== Gazebo =============== -->
  <gazebo>
    <plugin filename="libgazebo_ros_control.so" name="gazebo_ros_control"/>
  </gazebo>
  <gazebo reference="base_link">
    <selfCollide>false</selfCollide>
    <mu1 value="0.05"/>
    <mu2 value="0.05"/>
  </gazebo>
  <gazebo reference="right_front_wheel_link">
    <selfCollide>false</selfCollide>
    <mu1 value="0.8"/>
    <mu2 value="0.8"/>
  </gazebo>
  <gazebo reference="left_front_wheel_link">
    <selfCollide>false</selfCollide>
    <mu1 value="0.8"/>
    <mu2 value="0.8"/>
  </gazebo>
  <gazebo reference="right_rear_wheel_link">
    <selfCollide>false</selfCollide>
    <mu1 value="0.8"/>
    <mu2 value="0.8"/>
  </gazebo>
  <gazebo reference="left_rear_wheel_link">
    <selfCollide>false</selfCollide>
    <mu1 value="0.8"/>
    <mu2 value="0.8"/>
  </gazebo>
  <gazebo reference="laser_frame">
    <material>Gazebo/Red</material>
    <sensor name="laser" type="ray">
      <pose>0 0 0 0 0 0</pose>
      <visualize>true</visualize>
      <update_rate>1000</update_rate>
      <ray>
        <scan>
          <horizontal>
            <samples>360</samples>
            <min_angle>-3.14</min_angle>
            <max_angle>3.14</max_angle>
          </horizontal>
        </scan>
        <range>
          <min>0.45</min>
          <max>12</max>
        </range>
      </ray>
      <plugin filename="libgazebo_ros_laser.so" name="laser_controller">
        <topicName>/scan</topicName>
        <frameName>laser_frame</frameName>
      </plugin>
    </sensor>
  </gazebo>
</robot>

